Workbook

Sheet YAMAZUMI цеха
H1: YAMAZUMI ""
H2: Количество операций: | M2: Расчётное количество операторов: | R2: Дата разработки: | V2: Разработал: | Z2: СТ расч: | AC2: =MAX(E5:E12)*1.2 -> 0 | AH2: расч. кол-во изделий
H3: =COUNTA(I16:I153,N16:N153,S16:S153,X16:X153,AC16:AC153,AH16:AH153,AM16:AM153,AR16:AR153) -> 0 | Z3: СТ: | AC3: =MAX(E5:E12) -> 0 | AH3: =25200/AC2 -> #DIV/0!
B4: Раб.места | C4: Польза | D4: Потери | E4: Общее | F4: ТТ
B5: МЕХ СБ | C5: =J15 -> 0 | D5: =K15 -> 0 | E5: =L15 -> 0 | F5: =AC2 -> 0
B6: ППМ | C6: =O15 -> 0 | D6: =P15 -> 0 | E6: =Q15 -> 0 | F6: =AC2 -> 0
B7: РЕГУЛИРОВКА | C7: =T15 -> 0 | D7: =U15 -> 0 | E7: =V15 -> 0 | F7: =AC2 -> 0
B8: ПРСБ | C8: =Y15 -> 0 | D8: =Z15 -> 0 | E8: =AA15 -> 0 | F8: =AC2 -> 0
B9: ПРОГОН | C9: =AD15 -> 0 | D9: =AE15 -> 0 | E9: =AF15 -> 0 | F9: =AC2 -> 0
B10: ЛИНЗЫ | C10: =AI15 -> 0 | D10: =AJ15 -> 0 | E10: =AK15 -> 0 | F10: =AC2 -> 0
B11: СБОРКА | C11: =AN15 -> 0 | D11: =AO15 -> 0 | E11: =AP15 -> 0 | F11: =AC2 -> 0
B12: УПАКОВКА | C12: =AS15 -> 0 | D12: =AT15 -> 0 | E12: =AU15 -> 0 | F12: =AC2 -> 0
H14: № | I14: МЕХ СБ | J14: Польза | K14: Потери | L14: Общее | M14: № | N14: ППМ | O14: Польза | P14: Потери | Q14: Общее | R14: № | S14: РЕГУЛИРОВКА | T14: Польза | U14: Потери | V14: Общее | W14: № | X14: ПРСБ | Y14: Польза | Z14: Потери | AA14: Общее | AB14: № | AC14: ПРОГОН | AD14: Польза | AE14: Потери | AF14: Общее | AG14: № | AH14: ЛИНЗЫ | AI14: Польза | AJ14: Потери | AK14: Общее | AL14: № | AM14: СБОРКА | AN14: Польза | AO14: Потери | AP14: Общее | AQ14: № | AR14: УПАКОВКА | AS14: Польза | AT14: Потери | AU14: Общее
I15: Суммарное время: | J15: =SUM(J16:J71) -> 0 | K15: =SUM(K16:K71) -> 0 | L15: =SUM(L16:L71) -> 0 | N15: Суммарное время: | O15: =SUM(O16:O71) -> 0 | P15: =SUM(P16:P71) -> 0 | Q15: =SUM(Q16:Q71) -> 0 | S15: Суммарное время: | T15: =SUM(T16:T71) -> 0 | U15: =SUM(U16:U71) -> 0 | V15: =SUM(V16:V71) -> 0 | X15: Суммарное время: | Y15: =SUM(Y16:Y71) -> 0 | Z15: =SUM(Z16:Z71) -> 0 | AA15: =SUM(AA16:AA71) -> 0 | AC15: Суммарное время: | AD15: =SUM(AD16:AD71) -> 0 | AE15: =SUM(AE16:AE71) -> 0 | AF15: =SUM(AF16:AF71) -> 0 | AH15: Суммарное время: | AI15: =SUM(AI16:AI71) -> 0 | AJ15: =SUM(AJ16:AJ71) -> 0 | AK15: =SUM(AK16:AK71) -> 0 | AM15: Суммарное время: | AN15: =SUM(AN16:AN71) -> 0 | AO15: =SUM(AO16:AO71) -> 0 | AP15: =SUM(AP16:AP71) -> 0 | AR15: Суммарное время: | AS15: =SUM(AS16:AS71) -> 0 | AT15: =SUM(AT16:AT71) -> 0 | AU15: =SUM(AU16:AU71) -> 0
H16: 1 | L16: =SUM(J16:K16) -> 0 | M16: 1 | Q16: =SUM(O16:P16) -> 0 | R16: 1 | V16: =SUM(T16:U16) -> 0 | W16: 1 | AA16: =SUM(Y16:Z16) -> 0 | AB16: 1 | AF16: =SUM(AD16:AE16) -> 0 | AG16: 1 | AK16: =SUM(AI16:AJ16) -> 0 | AL16: 1 | AP16: =SUM(AN16:AO16) -> 0 | AQ16: 1 | AU16: =SUM(AS16:AT16) -> 0
H17: 2 | L17: =SUM(J17:K17) -> 0 | M17: 2 | Q17: =SUM(O17:P17) -> 0 | R17: 2 | V17: =SUM(T17:U17) -> 0 | W17: 2 | AA17: =SUM(Y17:Z17) -> 0 | AB17: 2 | AF17: =SUM(AD17:AE17) -> 0 | AG17: 2 | AK17: =SUM(AI17:AJ17) -> 0 | AL17: 2 | AP17: =SUM(AN17:AO17) -> 0 | AQ17: 2 | AU17: =SUM(AS17:AT17) -> 0
H18: 3 | L18: =SUM(J18:K18) -> 0 | M18: 3 | Q18: =SUM(O18:P18) -> 0 | R18: 3 | V18: =SUM(T18:U18) -> 0 | W18: 3 | AA18: =SUM(Y18:Z18) -> 0 | AB18: 3 | AF18: =SUM(AD18:AE18) -> 0 | AG18: 3 | AK18: =SUM(AI18:AJ18) -> 0 | AL18: 3 | AP18: =SUM(AN18:AO18) -> 0 | AQ18: 3 | AU18: =SUM(AS18:AT18) -> 0
H19: 4 | L19: =SUM(J19:K19) -> 0 | M19: 4 | Q19: =SUM(O19:P19) -> 0 | R19: 4 | V19: =SUM(T19:U19) -> 0 | W19: 4 | AA19: =SUM(Y19:Z19) -> 0 | AB19: 4 | AF19: =SUM(AD19:AE19) -> 0 | AG19: 4 | AK19: =SUM(AI19:AJ19) -> 0 | AL19: 4 | AP19: =SUM(AN19:AO19) -> 0 | AQ19: 4 | AU19: =SUM(AS19:AT19) -> 0
H20: 5 | L20: =SUM(J20:K20) -> 0 | M20: 5 | Q20: =SUM(O20:P20) -> 0 | R20: 5 | V20: =SUM(T20:U20) -> 0 | W20: 5 | AA20: =SUM(Y20:Z20) -> 0 | AB20: 5 | AF20: =SUM(AD20:AE20) -> 0 | AG20: 5 | AK20: =SUM(AI20:AJ20) -> 0 | AL20: 5 | AP20: =SUM(AN20:AO20) -> 0 | AQ20: 5 | AU20: =SUM(AS20:AT20) -> 0
H21: 6 | L21: =SUM(J21:K21) -> 0 | M21: 6 | Q21: =SUM(O21:P21) -> 0 | R21: 6 | V21: =SUM(T21:U21) -> 0 | W21: 6 | AA21: =SUM(Y21:Z21) -> 0 | AB21: 6 | AF21: =SUM(AD21:AE21) -> 0 | AG21: 6 | AK21: =SUM(AI21:AJ21) -> 0 | AL21: 6 | AP21: =SUM(AN21:AO21) -> 0 | AQ21: 6 | AU21: =SUM(AS21:AT21) -> 0
H22: 7 | L22: =SUM(J22:K22) -> 0 | M22: 7 | Q22: =SUM(O22:P22) -> 0 | R22: 7 | V22: =SUM(T22:U22) -> 0 | W22: 7 | AA22: =SUM(Y22:Z22) -> 0 | AB22: 7 | AF22: =SUM(AD22:AE22) -> 0 | AG22: 7 | AK22: =SUM(AI22:AJ22) -> 0 | AL22: 7 | AP22: =SUM(AN22:AO22) -> 0 | AQ22: 7 | AU22: =SUM(AS22:AT22) -> 0
H23: 8 | L23: =SUM(J23:K23) -> 0 | M23: 8 | Q23: =SUM(O23:P23) -> 0 | R23: 8 | V23: =SUM(T23:U23) -> 0 | W23: 8 | AA23: =SUM(Y23:Z23) -> 0 | AB23: 8 | AF23: =SUM(AD23:AE23) -> 0 | AG23: 8 | AK23: =SUM(AI23:AJ23) -> 0 | AL23: 8 | AP23: =SUM(AN23:AO23) -> 0 | AQ23: 8 | AU23: =SUM(AS23:AT23) -> 0
H24: 9 | L24: =SUM(J24:K24) -> 0 | M24: 9 | Q24: =SUM(O24:P24) -> 0 | R24: 9 | V24: =SUM(T24:U24) -> 0 | W24: 9 | AA24: =SUM(Y24:Z24) -> 0 | AB24: 9 | AF24: =SUM(AD24:AE24) -> 0 | AG24: 9 | AK24: =SUM(AI24:AJ24) -> 0 | AL24: 9 | AP24: =SUM(AN24:AO24) -> 0 | AQ24: 9 | AU24: =SUM(AS24:AT24) -> 0
H25: 10 | L25: =SUM(J25:K25) -> 0 | M25: 10 | Q25: =SUM(O25:P25) -> 0 | R25: 10 | V25: =SUM(T25:U25) -> 0 | W25: 10 | AA25: =SUM(Y25:Z25) -> 0 | AB25: 10 | AF25: =SUM(AD25:AE25) -> 0 | AG25: 10 | AK25: =SUM(AI25:AJ25) -> 0 | AL25: 10 | AP25: =SUM(AN25:AO25) -> 0 | AQ25: 10 | AU25: =SUM(AS25:AT25) -> 0
H26: 11 | L26: =SUM(J26:K26) -> 0 | M26: 11 | Q26: =SUM(O26:P26) -> 0 | R26: 11 | V26: =SUM(T26:U26) -> 0 | W26: 11 | AA26: =SUM(Y26:Z26) -> 0 | AB26: 11 | AF26: =SUM(AD26:AE26) -> 0 | AG26: 11 | AK26: =SUM(AI26:AJ26) -> 0 | AL26: 11 | AP26: =SUM(AN26:AO26) -> 0 | AQ26: 11 | AU26: =SUM(AS26:AT26) -> 0
H27: 12 | L27: =SUM(J27:K27) -> 0 | M27: 12 | Q27: =SUM(O27:P27) -> 0 | R27: 12 | V27: =SUM(T27:U27) -> 0 | W27: 12 | AA27: =SUM(Y27:Z27) -> 0 | AB27: 12 | AF27: =SUM(AD27:AE27) -> 0 | AG27: 12 | AK27: =SUM(AI27:AJ27) -> 0 | AL27: 12 | AP27: =SUM(AN27:AO27) -> 0 | AQ27: 12 | AU27: =SUM(AS27:AT27) -> 0
... H165: 150 | L165: =SUM(J165:K165) -> 0 | M165: 150 | Q165: =SUM(O165:P165) -> 0 | R165: 150 | V165: =SUM(T165:U165) -> 0 | W165: 150 | AA165: =SUM(Y165:Z165) -> 0 | AB165: 150 | AF165: =SUM(AD165:AE165) -> 0 | AG165: 150 | AK165: =SUM(AI165:AJ165) -> 0 | AL165: 150 | AP165: =SUM(AN165:AO165) -> 0 | AQ165: 150 | AU165: =SUM(AS165:AT165) -> 0

Sheet Механический
H1: ='YAMAZUMI цеха'!H1 -> YAMAZUMI ""
H2: Количество операций: | M2: Расчётное количество операторов: | R2: Дата разработки: | V2: Разработал: | Z2: СТ расч: | AC2: =MAX(E5:E14)*1.1 -> 0 | AE2: расч. кол-во изделий
H3: =COUNTA(I18:I153,N18:N153,S18:S153,X18:X153,AC18:AC153) -> 0 | M3: =COUNTA(I18,N18,S18,X18,AC18) -> 0 | R3: ='YAMAZUMI цеха'!R3 -> 0 | Z3: СТ: | AC3: =MAX(E5:E14) -> 0 | AE3: =26700/AC2 -> #DIV/0!
B4: Раб.места | C4: Польза | D4: Потери | E4: Общее | F4: ТТ
B5: Первое раб.место | C5: =J17 -> 0 | D5: =K17 -> 0 | E5: =L17 -> 0 | F5: =AC2 -> 0
B6: Второе раб.место | C6: =O17 -> 0 | D6: =P17 -> 0 | E6: =Q17 -> 0 | F6: =AC2 -> 0
B7: Третье раб.место | C7: =T17 -> 0 | D7: =U17 -> 0 | E7: =V17 -> 0 | F7: =AC2 -> 0
B8: Четвёртое раб.место | C8: =Y17 -> 0 | D8: =Z17 -> 0 | E8: =AA17 -> 0 | F8: =AC2 -> 0
B9: Пятое раб.место | C9: =AD17 -> 0 | D9: =AE17 -> 0 | E9: =AF17 -> 0 | F9: =AC2 -> 0
B10: Шестое раб.место | C10: =AI17 -> 0 | D10: =AJ17 -> 0 | E10: =AK17 -> 0 | F10: =AC2 -> 0
B11: Седьмое раб.место | C11: =AN17 -> 0 | D11: =AO17 -> 0 | E11: =AP17 -> 0 | F11: =AC2 -> 0
B12: Восьмое раб.место | C12: =AS17 -> 0 | D12: =AT17 -> 0 | E12: =AU17 -> 0 | F12: =AC2 -> 0
B13: Девятое раб.место | C13: =AX17 -> 0 | D13: =AY17 -> 0 | E13: =AZ17 -> 0 | F13: =AC2 -> 0
B14: Десятое раб.место | C14: =BC17 -> 0 | D14: =BD17 -> 0 | E14: =BE17 -> 0 | F14: =AC2 -> 0
H16: № | I16: Первое раб.место | J16: Польза | K16: Потери | L16: Общее | M16: № | N16: Второе раб.место | O16: Польза | P16: Потери | Q16: Общее | R16: № | S16: Третье раб.место | T16: Польза | U16: Потери | V16: Общее | W16: № | X16: Четвёртое раб.место | Y16: Польза | Z16: Потери | AA16: Общее | AB16: № | AC16: Пятое раб.место | AD16: Польза | AE16: Потери | AF16: Общее | AG16: № | AH16: Шестое раб.место | AI16: Польза | AJ16: Потери | AK16: Общее | AL16: № | AM16: Седьмое раб.место | AN16: Польза | AO16: Потери | AP16: Общее | AQ16: № | AR16: Восьмое раб.место | AS16: Польза | AT16: Потери | AU16: Общее | AV16: № | AW16: Девятое раб.место | AX16: Польза | AY16: Потери | AZ16: Общее | BA16: № | BB16: Десятое раб.место | BC16: Польза | BD16: Потери | BE16: Общее
I17: Суммарное время: | J17: =SUM(J18:J73) -> 0 | K17: =SUM(K18:K73) -> 0 | L17: =SUM(L18:L73) -> 0 | N17: Суммарное время: | O17: =SUM(O18:O73) -> 0 | P17: =SUM(P18:P73) -> 0 | Q17: =SUM(Q18:Q73) -> 0 | S17: Суммарное время: | T17: =SUM(T18:T73) -> 0 | U17: =SUM(U18:U73) -> 0 | V17: =SUM(V18:V73) -> 0 | X17: Суммарное время: | Y17: =SUM(Y18:Y73) -> 0 | Z17: =SUM(Z18:Z73) -> 0 | AA17: =SUM(AA18:AA73) -> 0 | AC17: Суммарное время: | AD17: =SUM(AD18:AD73) -> 0 | AE17: =SUM(AE18:AE73) -> 0 | AF17: =SUM(AF18:AF73) -> 0 | AH17: Суммарное время: | AI17: =SUM(AI18:AI73) -> 0 | AJ17: =SUM(AJ18:AJ73) -> 0 | AK17: =SUM(AK18:AK73) -> 0 | AM17: Суммарное время: | AN17: =SUM(AN18:AN73) -> 0 | AO17: =SUM(AO18:AO73) -> 0 | AP17: =SUM(AP18:AP73) -> 0 | AR17: Суммарное время: | AS17: =SUM(AS18:AS73) -> 0 | AT17: =SUM(AT18:AT73) -> 0 | AU17: =SUM(AU18:AU73) -> 0 | AW17: Суммарное время: | AX17: =SUM(AX18:AX73) -> 0 | AY17: =SUM(AY18:AY73) -> 0 | AZ17: =SUM(AZ18:AZ73) -> 0 | BB17: Суммарное время: | BC17: =SUM(BC18:BC73) -> 0 | BD17: =SUM(BD18:BD73) -> 0 | BE17: =SUM(BE18:BE73) -> 0
H18: 1 | L18: =SUM(J18:K18) -> 0 | M18: 1 | Q18: =SUM(O18:P18) -> 0 | R18: 1 | V18: =SUM(T18:U18) -> 0 | W18: 1 | AA18: =SUM(Y18:Z18) -> 0 | AB18: 1 | AF18: =SUM(AD18:AE18) -> 0 | AG18: 1 | AK18: =SUM(AI18:AJ18) -> 0 | AL18: 1 | AP18: =SUM(AN18:AO18) -> 0 | AQ18: 1 | AU18: =SUM(AS18:AT18) -> 0 | AV18: 1 | AZ18: =SUM(AX18:AY18) -> 0 | BA18: 1 | BE18: =SUM(BC18:BD18) -> 0
H19: 2 | L19: =SUM(J19:K19) -> 0 | M19: 2 | Q19: =SUM(O19:P19) -> 0 | R19: 2 | V19: =SUM(T19:U19) -> 0 | W19: 2 | AA19: =SUM(Y19:Z19) -> 0 | AB19: 2 | AF19: =SUM(AD19:AE19) -> 0 | AG19: 2 | AK19: =SUM(AI19:AJ19) -> 0 | AL19: 2 | AP19: =SUM(AN19:AO19) -> 0 | AQ19: 2 | AU19: =SUM(AS19:AT19) -> 0 | AV19: 2 | AZ19: =SUM(AX19:AY19) -> 0 | BA19: 2 | BE19: =SUM(BC19:BD19) -> 0
H20: 3 | L20: =SUM(J20:K20) -> 0 | M20: 3 | Q20: =SUM(O20:P20) -> 0 | R20: 3 | V20: =SUM(T20:U20) -> 0 | W20: 3 | AA20: =SUM(Y20:Z20) -> 0 | AB20: 3 | AF20: =SUM(AD20:AE20) -> 0 | AG20: 3 | AK20: =SUM(AI20:AJ20) -> 0 | AL20: 3 | AP20: =SUM(AN20:AO20) -> 0 | AQ20: 3 | AU20: =SUM(AS20:AT20) -> 0 | AV20: 3 | AZ20: =SUM(AX20:AY20) -> 0 | BA20: 3 | BE20: =SUM(BC20:BD20) -> 0
H21: 4 | L21: =SUM(J21:K21) -> 0 | M21: 4 | Q21: =SUM(O21:P21) -> 0 | R21: 4 | V21: =SUM(T21:U21) -> 0 | W21: 4 | AA21: =SUM(Y21:Z21) -> 0 | AB21: 4 | AF21: =SUM(AD21:AE21) -> 0 | AG21: 4 | AK21: =SUM(AI21:AJ21) -> 0 | AL21: 4 | AP21: =SUM(AN21:AO21) -> 0 | AQ21: 4 | AU21: =SUM(AS21:AT21) -> 0 | AV21: 4 | AZ21: =SUM(AX21:AY21) -> 0 | BA21: 4 | BE21: =SUM(BC21:BD21) -> 0
H22: 5 | L22: =SUM(J22:K22) -> 0 | M22: 5 | Q22: =SUM(O22:P22) -> 0 | R22: 5 | V22: =SUM(T22:U22) -> 0 | W22: 5 | AA22: =SUM(Y22:Z22) -> 0 | AB22: 5 | AF22: =SUM(AD22:AE22) -> 0 | AG22: 5 | AK22: =SUM(AI22:AJ22) -> 0 | AL22: 5 | AP22: =SUM(AN22:AO22) -> 0 | AQ22: 5 | AU22: =SUM(AS22:AT22) -> 0 | AV22: 5 | AZ22: =SUM(AX22:AY22) -> 0 | BA22: 5 | BE22: =SUM(BC22:BD22) -> 0
H23: 6 | L23: =SUM(J23:K23) -> 0 | M23: 6 | Q23: =SUM(O23:P23) -> 0 | R23: 6 | V23: =SUM(T23:U23) -> 0 | W23: 6 | AA23: =SUM(Y23:Z23) -> 0 | AB23: 6 | AF23: =SUM(AD23:AE23) -> 0 | AG23: 6 | AK23: =SUM(AI23:AJ23) -> 0 | AL23: 6 | AP23: =SUM(AN23:AO23) -> 0 | AQ23: 6 | AU23: =SUM(AS23:AT23) -> 0 | AV23: 6 | AZ23: =SUM(AX23:AY23) -> 0 | BA23: 6 | BE23: =SUM(BC23:BD23) -> 0
H24: 7 | L24: =SUM(J24:K24) -> 0 | M24: 7 | Q24: =SUM(O24:P24) -> 0 | R24: 7 | V24: =SUM(T24:U24) -> 0 | W24: 7 | AA24: =SUM(Y24:Z24) -> 0 | AB24: 7 | AF24: =SUM(AD24:AE24) -> 0 | AG24: 7 | AK24: =SUM(AI24:AJ24) -> 0 | AL24: 7 | AP24: =SUM(AN24:AO24) -> 0 | AQ24: 7 | AU24: =SUM(AS24:AT24) -> 0 | AV24: 7 | AZ24: =SUM(AX24:AY24) -> 0 | BA24: 7 | BE24: =SUM(BC24:BD24) -> 0
H25: 8 | L25: =SUM(J25:K25) -> 0 | M25: 8 | Q25: =SUM(O25:P25) -> 0 | R25: 8 | V25: =SUM(T25:U25) -> 0 | W25: 8 | AA25: =SUM(Y25:Z25) -> 0 | AB25: 8 | AF25: =SUM(AD25:AE25) -> 0 | AG25: 8 | AK25: =SUM(AI25:AJ25) -> 0 | AL25: 8 | AP25: =SUM(AN25:AO25) -> 0 | AQ25: 8 | AU25: =SUM(AS25:AT25) -> 0 | AV25: 8 | AZ25: =SUM(AX25:AY25) -> 0 | BA25: 8 | BE25: =SUM(BC25:BD25) -> 0
H26: 9 | L26: =SUM(J26:K26) -> 0 | M26: 9 | Q26: =SUM(O26:P26) -> 0 | R26: 9 | V26: =SUM(T26:U26) -> 0 | W26: 9 | AA26: =SUM(Y26:Z26) -> 0 | AB26: 9 | AF26: =SUM(AD26:AE26) -> 0 | AG26: 9 | AK26: =SUM(AI26:AJ26) -> 0 | AL26: 9 | AP26: =SUM(AN26:AO26) -> 0 | AQ26: 9 | AU26: =SUM(AS26:AT26) -> 0 | AV26: 9 | AZ26: =SUM(AX26:AY26) -> 0 | BA26: 9 | BE26: =SUM(BC26:BD26) -> 0
H27: 10 | L27: =SUM(J27:K27) -> 0 | M27: 10 | Q27: =SUM(O27:P27) -> 0 | R27: 10 | V27: =SUM(T27:U27) -> 0 | W27: 10 | AA27: =SUM(Y27:Z27) -> 0 | AB27: 10 | AF27: =SUM(AD27:AE27) -> 0 | AG27: 10 | AK27: =SUM(AI27:AJ27) -> 0 | AL27: 10 | AP27: =SUM(AN27:AO27) -> 0 | AQ27: 10 | AU27: =SUM(AS27:AT27) -> 0 | AV27: 10 | AZ27: =SUM(AX27:AY27) -> 0 | BA27: 10 | BE27: =SUM(BC27:BD27) -> 0
H28: 11 | L28: =SUM(J28:K28) -> 0 | M28: 11 | Q28: =SUM(O28:P28) -> 0 | R28: 11 | V28: =SUM(T28:U28) -> 0 | W28: 11 | AA28: =SUM(Y28:Z28) -> 0 | AB28: 11 | AF28: =SUM(AD28:AE28) -> 0 | AG28: 11 | AK28: =SUM(AI28:AJ28) -> 0 | AL28: 11 | AP28: =SUM(AN28:AO28) -> 0 | AQ28: 11 | AU28: =SUM(AS28:AT28) -> 0 | AV28: 11 | AZ28: =SUM(AX28:AY28) -> 0 | BA28: 11 | BE28: =SUM(BC28:BD28) -> 0
H29: 12 | L29: =SUM(J29:K29) -> 0 | M29: 12 | Q29: =SUM(O29:P29) -> 0 | R29: 12 | V29: =SUM(T29:U29) -> 0 | W29: 12 | AA29: =SUM(Y29:Z29) -> 0 | AB29: 12 | AF29: =SUM(AD29:AE29) -> 0 | AG29: 12 | AK29: =SUM(AI29:AJ29) -> 0 | AL29: 12 | AP29: =SUM(AN29:AO29) -> 0 | AQ29: 12 | AU29: =SUM(AS29:AT29) -> 0 | AV29: 12 | AZ29: =SUM(AX29:AY29) -> 0 | BA29: 12 | BE29: =SUM(BC29:BD29) -> 0
... H73: 56 | L73: =SUM(J73:K73) -> 0 | M73: 56 | Q73: =SUM(O73:P73) -> 0 | R73: 56 | V73: =SUM(T73:U73) -> 0 | W73: 56 | AA73: =SUM(Y73:Z73) -> 0 | AB73: 56 | AF73: =SUM(AD73:AE73) -> 0 | AG73: 56 | AK73: =SUM(AI73:AJ73) -> 0 | AL73: 56 | AP73: =SUM(AN73:AO73) -> 0 | AQ73: 56 | AU73: =SUM(AS73:AT73) -> 0 | AV73: 56 | AZ73: =SUM(AX73:AY73) -> 0 | BA73: 56 | BE73: =SUM(BC73:BD73) -> 0

Sheet Фрезеровка ЧПУ
H1: ='YAMAZUMI цеха'!H1 -> YAMAZUMI ""
H2: Количество операций: | M2: Расчётное количество операторов: | R2: Дата разработки: | V2: Разработал: | Z2: СТ расч: | AC2: =MAX(E5:E14)*1.1 -> 0 | AE2: расч. кол-во изделий
H3: =COUNTA(I18:I153,N18:N153,S18:S153,X18:X153,AC18:AC153) -> 0 | M3: =COUNTA(I18,N18,S18,X18,AC18) -> 0 | R3: ='YAMAZUMI цеха'!R3 -> 0 | Z3: СТ: | AC3: =MAX(E5:E14) -> 0 | AE3: =26700/AC2 -> #DIV/0!
B4: Раб.места | C4: Польза | D4: Потери | E4: Общее | F4: ТТ
B5: Первое раб.место | C5: =J17 -> 0 | D5: =K17 -> 0 | E5: =L17 -> 0 | F5: =AC2 -> 0
B6: Второе раб.место | C6: =O17 -> 0 | D6: =P17 -> 0 | E6: =Q17 -> 0 | F6: =AC2 -> 0
B7: Третье раб.место | C7: =T17 -> 0 | D7: =U17 -> 0 | E7: =V17 -> 0 | F7: =AC2 -> 0
B8: Четвёртое раб.место | C8: =Y17 -> 0 | D8: =Z17 -> 0 | E8: =AA17 -> 0 | F8: =AC2 -> 0
B9: Пятое раб.место | C9: =AD17 -> 0 | D9: =AE17 -> 0 | E9: =AF17 -> 0 | F9: =AC2 -> 0
B10: Шестое раб.место | C10: =AI17 -> 0 | D10: =AJ17 -> 0 | E10: =AK17 -> 0 | F10: =AC2 -> 0
B11: Седьмое раб.место | C11: =AN17 -> 0 | D11: =AO17 -> 0 | E11: =AP17 -> 0 | F11: =AC2 -> 0
B12: Восьмое раб.место | C12: =AS17 -> 0 | D12: =AT17 -> 0 | E12: =AU17 -> 0 | F12: =AC2 -> 0
B13: Девятое раб.место | C13: =AX17 -> 0 | D13: =AY17 -> 0 | E13: =AZ17 -> 0 | F13: =AC2 -> 0
B14: Десятое раб.место | C14: =BC17 -> 0 | D14: =BD17 -> 0 | E14: =BE17 -> 0 | F14: =AC2 -> 0
H16: № | I16: Первое раб.место | J16: Польза | K16: Потери | L16: Общее | M16: № | N16: Второе раб.место | O16: Польза | P16: Потери | Q16: Общее | R16: № | S16: Третье раб.место | T16: Польза | U16: Потери | V16: Общее | W16: № | X16: Четвёртое раб.место | Y16: Польза | Z16: Потери | AA16: Общее | AB16: № | AC16: Пятое раб.место | AD16: Польза | AE16: Потери | AF16: Общее | AG16: № | AH16: Шестое раб.место | AI16: Польза | AJ16: Потери | AK16: Общее | AL16: № | AM16: Седьмое раб.место | AN16: Польза | AO16: Потери | AP16: Общее | AQ16: № | AR16: Восьмое раб.место | AS16: Польза | AT16: Потери | AU16: Общее | AV16: № | AW16: Девятое раб.место | AX16: Польза | AY16: Потери | AZ16: Общее | BA16: № | BB16: Десятое раб.место | BC16: Польза | BD16: Потери | BE16: Общее
I17: Суммарное время: | J17: =SUM(J18:J73) -> 0 | K17: =SUM(K18:K73) -> 0 | L17: =SUM(L18:L73) -> 0 | N17: Суммарное время: | O17: =SUM(O18:O73) -> 0 | P17: =SUM(P18:P73) -> 0 | Q17: =SUM(Q18:Q73) -> 0 | S17: Суммарное время: | T17: =SUM(T18:T73) -> 0 | U17: =SUM(U18:U73) -> 0 | V17: =SUM(V18:V73) -> 0 | X17: Суммарное время: | Y17: =SUM(Y18:Y73) -> 0 | Z17: =SUM(Z18:Z73) -> 0 | AA17: =SUM(AA18:AA73) -> 0 | AC17: Суммарное время: | AD17: =SUM(AD18:AD73) -> 0 | AE17: =SUM(AE18:AE73) -> 0 | AF17: =SUM(AF18:AF73) -> 0 | AH17: Суммарное время: | AI17: =SUM(AI18:AI73) -> 0 | AJ17: =SUM(AJ18:AJ73) -> 0 | AK17: =SUM(AK18:AK73) -> 0 | AM17: Суммарное время: | AN17: =SUM(AN18:AN73) -> 0 | AO17: =SUM(AO18:AO73) -> 0 | AP17: =SUM(AP18:AP73) -> 0 | AR17: Суммарное время: | AS17: =SUM(AS18:AS73) -> 0 | AT17: =SUM(AT18:AT73) -> 0 | AU17: =SUM(AU18:AU73) -> 0 | AW17: Суммарное время: | AX17: =SUM(AX18:AX73) -> 0 | AY17: =SUM(AY18:AY73) -> 0 | AZ17: =SUM(AZ18:AZ73) -> 0 | BB17: Суммарное время: | BC17: =SUM(BC18:BC73) -> 0 | BD17: =SUM(BD18:BD73) -> 0 | BE17: =SUM(BE18:BE73) -> 0
H18: 1 | L18: =SUM(J18:K18) -> 0 | M18: 1 | Q18: =SUM(O18:P18) -> 0 | R18: 1 | V18: =SUM(T18:U18) -> 0 | W18: 1 | AA18: =SUM(Y18:Z18) -> 0 | AB18: 1 | AF18: =SUM(AD18:AE18) -> 0 | AG18: 1 | AK18: =SUM(AI18:AJ18) -> 0 | AL18: 1 | AP18: =SUM(AN18:AO18) -> 0 | AQ18: 1 | AU18: =SUM(AS18:AT18) -> 0 | AV18: 1 | AZ18: =SUM(AX18:AY18) -> 0 | BA18: 1 | BE18: =SUM(BC18:BD18) -> 0
H19: 2 | L19: =SUM(J19:K19) -> 0 | M19: 2 | Q19: =SUM(O19:P19) -> 0 | R19: 2 | V19: =SUM(T19:U19) -> 0 | W19: 2 | AA19: =SUM(Y19:Z19) -> 0 | AB19: 2 | AF19: =SUM(AD19:AE19) -> 0 | AG19: 2 | AK19: =SUM(AI19:AJ19) -> 0 | AL19: 2 | AP19: =SUM(AN19:AO19) -> 0 | AQ19: 2 | AU19: =SUM(AS19:AT19) -> 0 | AV19: 2 | AZ19: =SUM(AX19:AY19) -> 0 | BA19: 2 | BE19: =SUM(BC19:BD19) -> 0
H20: 3 | L20: =SUM(J20:K20) -> 0 | M20: 3 | Q20: =SUM(O20:P20) -> 0 | R20: 3 | V20: =SUM(T20:U20) -> 0 | W20: 3 | AA20: =SUM(Y20:Z20) -> 0 | AB20: 3 | AF20: =SUM(AD20:AE20) -> 0 | AG20: 3 | AK20: =SUM(AI20:AJ20) -> 0 | AL20: 3 | AP20: =SUM(AN20:AO20) -> 0 | AQ20: 3 | AU20: =SUM(AS20:AT20) -> 0 | AV20: 3 | AZ20: =SUM(AX20:AY20) -> 0 | BA20: 3 | BE20: =SUM(BC20:BD20) -> 0
H21: 4 | L21: =SUM(J21:K21) -> 0 | M21: 4 | Q21: =SUM(O21:P21) -> 0 | R21: 4 | V21: =SUM(T21:U21) -> 0 | W21: 4 | AA21: =SUM(Y21:Z21) -> 0 | AB21: 4 | AF21: =SUM(AD21:AE21) -> 0 | AG21: 4 | AK21: =SUM(AI21:AJ21) -> 0 | AL21: 4 | AP21: =SUM(AN21:AO21) -> 0 | AQ21: 4 | AU21: =SUM(AS21:AT21) -> 0 | AV21: 4 | AZ21: =SUM(AX21:AY21) -> 0 | BA21: 4 | BE21: =SUM(BC21:BD21) -> 0
H22: 5 | L22: =SUM(J22:K22) -> 0 | M22: 5 | Q22: =SUM(O22:P22) -> 0 | R22: 5 | V22: =SUM(T22:U22) -> 0 | W22: 5 | AA22: =SUM(Y22:Z22) -> 0 | AB22: 5 | AF22: =SUM(AD22:AE22) -> 0 | AG22: 5 | AK22: =SUM(AI22:AJ22) -> 0 | AL22: 5 | AP22: =SUM(AN22:AO22) -> 0 | AQ22: 5 | AU22: =SUM(AS22:AT22) -> 0 | AV22: 5 | AZ22: =SUM(AX22:AY22) -> 0 | BA22: 5 | BE22: =SUM(BC22:BD22) -> 0
H23: 6 | L23: =SUM(J23:K23) -> 0 | M23: 6 | Q23: =SUM(O23:P23) -> 0 | R23: 6 | V23: =SUM(T23:U23) -> 0 | W23: 6 | AA23: =SUM(Y23:Z23) -> 0 | AB23: 6 | AF23: =SUM(AD23:AE23) -> 0 | AG23: 6 | AK23: =SUM(AI23:AJ23) -> 0 | AL23: 6 | AP23: =SUM(AN23:AO23) -> 0 | AQ23: 6 | AU23: =SUM(AS23:AT23) -> 0 | AV23: 6 | AZ23: =SUM(AX23:AY23) -> 0 | BA23: 6 | BE23: =SUM(BC23:BD23) -> 0
H24: 7 | L24: =SUM(J24:K24) -> 0 | M24: 7 | Q24: =SUM(O24:P24) -> 0 | R24: 7 | V24: =SUM(T24:U24) -> 0 | W24: 7 | AA24: =SUM(Y24:Z24) -> 0 | AB24: 7 | AF24: =SUM(AD24:AE24) -> 0 | AG24: 7 | AK24: =SUM(AI24:AJ24) -> 0 | AL24: 7 | AP24: =SUM(AN24:AO24) -> 0 | AQ24: 7 | AU24: =SUM(AS24:AT24) -> 0 | AV24: 7 | AZ24: =SUM(AX24:AY24) -> 0 | BA24: 7 | BE24: =SUM(BC24:BD24) -> 0
H25: 8 | L25: =SUM(J25:K25) -> 0 | M25: 8 | Q25: =SUM(O25:P25) -> 0 | R25: 8 | V25: =SUM(T25:U25) -> 0 | W25: 8 | AA25: =SUM(Y25:Z25) -> 0 | AB25: 8 | AF25: =SUM(AD25:AE25) -> 0 | AG25: 8 | AK25: =SUM(AI25:AJ25) -> 0 | AL25: 8 | AP25: =SUM(AN25:AO25) -> 0 | AQ25: 8 | AU25: =SUM(AS25:AT25) -> 0 | AV25: 8 | AZ25: =SUM(AX25:AY25) -> 0 | BA25: 8 | BE25: =SUM(BC25:BD25) -> 0
H26: 9 | L26: =SUM(J26:K26) -> 0 | M26: 9 | Q26: =SUM(O26:P26) -> 0 | R26: 9 | V26: =SUM(T26:U26) -> 0 | W26: 9 | AA26: =SUM(Y26:Z26) -> 0 | AB26: 9 | AF26: =SUM(AD26:AE26) -> 0 | AG26: 9 | AK26: =SUM(AI26:AJ26) -> 0 | AL26: 9 | AP26: =SUM(AN26:AO26) -> 0 | AQ26: 9 | AU26: =SUM(AS26:AT26) -> 0 | AV26: 9 | AZ26: =SUM(AX26:AY26) -> 0 | BA26: 9 | BE26: =SUM(BC26:BD26) -> 0
H27: 10 | L27: =SUM(J27:K27) -> 0 | M27: 10 | Q27: =SUM(O27:P27) -> 0 | R27: 10 | V27: =SUM(T27:U27) -> 0 | W27: 10 | AA27: =SUM(Y27:Z27) -> 0 | AB27: 10 | AF27: =SUM(AD27:AE27) -> 0 | AG27: 10 | AK27: =SUM(AI27:AJ27) -> 0 | AL27: 10 | AP27: =SUM(AN27:AO27) -> 0 | AQ27: 10 | AU27: =SUM(AS27:AT27) -> 0 | AV27: 10 | AZ27: =SUM(AX27:AY27) -> 0 | BA27: 10 | BE27: =SUM(BC27:BD27) -> 0
H28: 11 | L28: =SUM(J28:K28) -> 0 | M28: 11 | Q28: =SUM(O28:P28) -> 0 | R28: 11 | V28: =SUM(T28:U28) -> 0 | W28: 11 | AA28: =SUM(Y28:Z28) -> 0 | AB28: 11 | AF28: =SUM(AD28:AE28) -> 0 | AG28: 11 | AK28: =SUM(AI28:AJ28) -> 0 | AL28: 11 | AP28: =SUM(AN28:AO28) -> 0 | AQ28: 11 | AU28: =SUM(AS28:AT28) -> 0 | AV28: 11 | AZ28: =SUM(AX28:AY28) -> 0 | BA28: 11 | BE28: =SUM(BC28:BD28) -> 0
H29: 12 | L29: =SUM(J29:K29) -> 0 | M29: 12 | Q29: =SUM(O29:P29) -> 0 | R29: 12 | V29: =SUM(T29:U29) -> 0 | W29: 12 | AA29: =SUM(Y29:Z29) -> 0 | AB29: 12 | AF29: =SUM(AD29:AE29) -> 0 | AG29: 12 | AK29: =SUM(AI29:AJ29) -> 0 | AL29: 12 | AP29: =SUM(AN29:AO29) -> 0 | AQ29: 12 | AU29: =SUM(AS29:AT29) -> 0 | AV29: 12 | AZ29: =SUM(AX29:AY29) -> 0 | BA29: 12 | BE29: =SUM(BC29:BD29) -> 0
... H73: 56 | L73: =SUM(J73:K73) -> 0 | M73: 56 | Q73: =SUM(O73:P73) -> 0 | R73: 56 | V73: =SUM(T73:U73) -> 0 | W73: 56 | AA73: =SUM(Y73:Z73) -> 0 | AB73: 56 | AF73: =SUM(AD73:AE73) -> 0 | AG73: 56 | AK73: =SUM(AI73:AJ73) -> 0 | AL73: 56 | AP73: =SUM(AN73:AO73) -> 0 | AQ73: 56 | AU73: =SUM(AS73:AT73) -> 0 | AV73: 56 | AZ73: =SUM(AX73:AY73) -> 0 | BA73: 56 | BE73: =SUM(BC73:BD73) -> 0

Sheet ППМ 3
H1: ='YAMAZUMI цеха'!H1 -> YAMAZUMI ""
H2: Количество операций: | M2: Расчётное количество операторов: | R2: Дата разработки: | V2: Разработал: | Z2: СТ расч: | AC2: =MAX(E5:E14)*1.1 -> 0 | AE2: расч. кол-во изделий
H3: =COUNTA(I18:I153,N18:N153,S18:S153,X18:X153,AC18:AC153) -> 0 | M3: =COUNTA(I18,N18,S18,X18,AC18) -> 0 | R3: ='YAMAZUMI цеха'!R3 -> 0 | Z3: СТ: | AC3: =MAX(E5:E14) -> 0 | AE3: =26700/AC2 -> #DIV/0!
B4: Раб.места | C4: Польза | D4: Потери | E4: Общее | F4: ТТ
B5: Первое раб.место | C5: =J17 -> 0 | D5: =K17 -> 0 | E5: =L17 -> 0 | F5: =AC2 -> 0
B6: Второе раб.место | C6: =O17 -> 0 | D6: =P17 -> 0 | E6: =Q17 -> 0 | F6: =AC2 -> 0
B7: Третье раб.место | C7: =T17 -> 0 | D7: =U17 -> 0 | E7: =V17 -> 0 | F7: =AC2 -> 0
B8: Четвёртое раб.место | C8: =Y17 -> 0 | D8: =Z17 -> 0 | E8: =AA17 -> 0 | F8: =AC2 -> 0
B9: Пятое раб.место | C9: =AD17 -> 0 | D9: =AE17 -> 0 | E9: =AF17 -> 0 | F9: =AC2 -> 0
B10: Шестое раб.место | C10: =AI17 -> 0 | D10: =AJ17 -> 0 | E10: =AK17 -> 0 | F10: =AC2 -> 0
B11: Седьмое раб.место | C11: =AN17 -> 0 | D11: =AO17 -> 0 | E11: =AP17 -> 0 | F11: =AC2 -> 0
B12: Восьмое раб.место | C12: =AS17 -> 0 | D12: =AT17 -> 0 | E12: =AU17 -> 0 | F12: =AC2 -> 0
B13: Девятое раб.место | C13: =AX17 -> 0 | D13: =AY17 -> 0 | E13: =AZ17 -> 0 | F13: =AC2 -> 0
B14: Десятое раб.место | C14: =BC17 -> 0 | D14: =BD17 -> 0 | E14: =BE17 -> 0 | F14: =AC2 -> 0
H16: № | I16: Первое раб.место | J16: Польза | K16: Потери | L16: Общее | M16: № | N16: Второе раб.место | O16: Польза | P16: Потери | Q16: Общее | R16: № | S16: Третье раб.место | T16: Польза | U16: Потери | V16: Общее | W16: № | X16: Четвёртое раб.место | Y16: Польза | Z16: Потери | AA16: Общее | AB16: № | AC16: Пятое раб.место | AD16: Польза | AE16: Потери | AF16: Общее | AG16: № | AH16: Шестое раб.место | AI16: Польза | AJ16: Потери | AK16: Общее | AL16: № | AM16: Седьмое раб.место | AN16: Польза | AO16: Потери | AP16: Общее | AQ16: № | AR16: Восьмое раб.место | AS16: Польза | AT16: Потери | AU16: Общее | AV16: № | AW16: Девятое раб.место | AX16: Польза | AY16: Потери | AZ16: Общее | BA16: № | BB16: Десятое раб.место | BC16: Польза | BD16: Потери | BE16: Общее
I17: Суммарное время: | J17: =SUM(J18:J73) -> 0 | K17: =SUM(K18:K73) -> 0 | L17: =SUM(L18:L73) -> 0 | N17: Суммарное время: | O17: =SUM(O18:O73) -> 0 | P17: =SUM(P18:P73) -> 0 | Q17: =SUM(Q18:Q73) -> 0 | S17: Суммарное время: | T17: =SUM(T18:T73) -> 0 | U17: =SUM(U18:U73) -> 0 | V17: =SUM(V18:V73) -> 0 | X17: Суммарное время: | Y17: =SUM(Y18:Y73) -> 0 | Z17: =SUM(Z18:Z73) -> 0 | AA17: =SUM(AA18:AA73) -> 0 | AC17: Суммарное время: | AD17: =SUM(AD18:AD73) -> 0 | AE17: =SUM(AE18:AE73) -> 0 | AF17: =SUM(AF18:AF73) -> 0 | AH17: Суммарное время: | AI17: =SUM(AI18:AI73) -> 0 | AJ17: =SUM(AJ18:AJ73) -> 0 | AK17: =SUM(AK18:AK73) -> 0 | AM17: Суммарное время: | AN17: =SUM(AN18:AN73) -> 0 | AO17: =SUM(AO18:AO73) -> 0 | AP17: =SUM(AP18:AP73) -> 0 | AR17: Суммарное время: | AS17: =SUM(AS18:AS73) -> 0 | AT17: =SUM(AT18:AT73) -> 0 | AU17: =SUM(AU18:AU73) -> 0 | AW17: Суммарное время: | AX17: =SUM(AX18:AX73) -> 0 | AY17: =SUM(AY18:AY73) -> 0 | AZ17: =SUM(AZ18:AZ73) -> 0 | BB17: Суммарное время: | BC17: =SUM(BC18:BC73) -> 0 | BD17: =SUM(BD18:BD73) -> 0 | BE17: =SUM(BE18:BE73) -> 0
H18: 1 | L18: =SUM(J18:K18) -> 0 | M18: 1 | Q18: =SUM(O18:P18) -> 0 | R18: 1 | V18: =SUM(T18:U18) -> 0 | W18: 1 | AA18: =SUM(Y18:Z18) -> 0 | AB18: 1 | AF18: =SUM(AD18:AE18) -> 0 | AG18: 1 | AK18: =SUM(AI18:AJ18) -> 0 | AL18: 1 | AP18: =SUM(AN18:AO18) -> 0 | AQ18: 1 | AU18: =SUM(AS18:AT18) -> 0 | AV18: 1 | AZ18: =SUM(AX18:AY18) -> 0 | BA18: 1 | BE18: =SUM(BC18:BD18) -> 0
H19: 2 | L19: =SUM(J19:K19) -> 0 | M19: 2 | Q19: =SUM(O19:P19) -> 0 | R19: 2 | V19: =SUM(T19:U19) -> 0 | W19: 2 | AA19: =SUM(Y19:Z19) -> 0 | AB19: 2 | AF19: =SUM(AD19:AE19) -> 0 | AG19: 2 | AK19: =SUM(AI19:AJ19) -> 0 | AL19: 2 | AP19: =SUM(AN19:AO19) -> 0 | AQ19: 2 | AU19: =SUM(AS19:AT19) -> 0 | AV19: 2 | AZ19: =SUM(AX19:AY19) -> 0 | BA19: 2 | BE19: =SUM(BC19:BD19) -> 0
H20: 3 | L20: =SUM(J20:K20) -> 0 | M20: 3 | Q20: =SUM(O20:P20) -> 0 | R20: 3 | V20: =SUM(T20:U20) -> 0 | W20: 3 | AA20: =SUM(Y20:Z20) -> 0 | AB20: 3 | AF20: =SUM(AD20:AE20) -> 0 | AG20: 3 | AK20: =SUM(AI20:AJ20) -> 0 | AL20: 3 | AP20: =SUM(AN20:AO20) -> 0 | AQ20: 3 | AU20: =SUM(AS20:AT20) -> 0 | AV20: 3 | AZ20: =SUM(AX20:AY20) -> 0 | BA20: 3 | BE20: =SUM(BC20:BD20) -> 0
H21: 4 | L21: =SUM(J21:K21) -> 0 | M21: 4 | Q21: =SUM(O21:P21) -> 0 | R21: 4 | V21: =SUM(T21:U21) -> 0 | W21: 4 | AA21: =SUM(Y21:Z21) -> 0 | AB21: 4 | AF21: =SUM(AD21:AE21) -> 0 | AG21: 4 | AK21: =SUM(AI21:AJ21) -> 0 | AL21: 4 | AP21: =SUM(AN21:AO21) -> 0 | AQ21: 4 | AU21: =SUM(AS21:AT21) -> 0 | AV21: 4 | AZ21: =SUM(AX21:AY21) -> 0 | BA21: 4 | BE21: =SUM(BC21:BD21) -> 0
H22: 5 | L22: =SUM(J22:K22) -> 0 | M22: 5 | Q22: =SUM(O22:P22) -> 0 | R22: 5 | V22: =SUM(T22:U22) -> 0 | W22: 5 | AA22: =SUM(Y22:Z22) -> 0 | AB22: 5 | AF22: =SUM(AD22:AE22) -> 0 | AG22: 5 | AK22: =SUM(AI22:AJ22) -> 0 | AL22: 5 | AP22: =SUM(AN22:AO22) -> 0 | AQ22: 5 | AU22: =SUM(AS22:AT22) -> 0 | AV22: 5 | AZ22: =SUM(AX22:AY22) -> 0 | BA22: 5 | BE22: =SUM(BC22:BD22) -> 0
H23: 6 | L23: =SUM(J23:K23) -> 0 | M23: 6 | Q23: =SUM(O23:P23) -> 0 | R23: 6 | V23: =SUM(T23:U23) -> 0 | W23: 6 | AA23: =SUM(Y23:Z23) -> 0 | AB23: 6 | AF23: =SUM(AD23:AE23) -> 0 | AG23: 6 | AK23: =SUM(AI23:AJ23) -> 0 | AL23: 6 | AP23: =SUM(AN23:AO23) -> 0 | AQ23: 6 | AU23: =SUM(AS23:AT23) -> 0 | AV23: 6 | AZ23: =SUM(AX23:AY23) -> 0 | BA23: 6 | BE23: =SUM(BC23:BD23) -> 0
H24: 7 | L24: =SUM(J24:K24) -> 0 | M24: 7 | Q24: =SUM(O24:P24) -> 0 | R24: 7 | V24: =SUM(T24:U24) -> 0 | W24: 7 | AA24: =SUM(Y24:Z24) -> 0 | AB24: 7 | AF24: =SUM(AD24:AE24) -> 0 | AG24: 7 | AK24: =SUM(AI24:AJ24) -> 0 | AL24: 7 | AP24: =SUM(AN24:AO24) -> 0 | AQ24: 7 | AU24: =SUM(AS24:AT24) -> 0 | AV24: 7 | AZ24: =SUM(AX24:AY24) -> 0 | BA24: 7 | BE24: =SUM(BC24:BD24) -> 0
H25: 8 | L25: =SUM(J25:K25) -> 0 | M25: 8 | Q25: =SUM(O25:P25) -> 0 | R25: 8 | V25: =SUM(T25:U25) -> 0 | W25: 8 | AA25: =SUM(Y25:Z25) -> 0 | AB25: 8 | AF25: =SUM(AD25:AE25) -> 0 | AG25: 8 | AK25: =SUM(AI25:AJ25) -> 0 | AL25: 8 | AP25: =SUM(AN25:AO25) -> 0 | AQ25: 8 | AU25: =SUM(AS25:AT25) -> 0 | AV25: 8 | AZ25: =SUM(AX25:AY25) -> 0 | BA25: 8 | BE25: =SUM(BC25:BD25) -> 0
H26: 9 | L26: =SUM(J26:K26) -> 0 | M26: 9 | Q26: =SUM(O26:P26) -> 0 | R26: 9 | V26: =SUM(T26:U26) -> 0 | W26: 9 | AA26: =SUM(Y26:Z26) -> 0 | AB26: 9 | AF26: =SUM(AD26:AE26) -> 0 | AG26: 9 | AK26: =SUM(AI26:AJ26) -> 0 | AL26: 9 | AP26: =SUM(AN26:AO26) -> 0 | AQ26: 9 | AU26: =SUM(AS26:AT26) -> 0 | AV26: 9 | AZ26: =SUM(AX26:AY26) -> 0 | BA26: 9 | BE26: =SUM(BC26:BD26) -> 0
H27: 10 | L27: =SUM(J27:K27) -> 0 | M27: 10 | Q27: =SUM(O27:P27) -> 0 | R27: 10 | V27: =SUM(T27:U27) -> 0 | W27: 10 | AA27: =SUM(Y27:Z27) -> 0 | AB27: 10 | AF27: =SUM(AD27:AE27) -> 0 | AG27: 10 | AK27: =SUM(AI27:AJ27) -> 0 | AL27: 10 | AP27: =SUM(AN27:AO27) -> 0 | AQ27: 10 | AU27: =SUM(AS27:AT27) -> 0 | AV27: 10 | AZ27: =SUM(AX27:AY27) -> 0 | BA27: 10 | BE27: =SUM(BC27:BD27) -> 0
H28: 11 | L28: =SUM(J28:K28) -> 0 | M28: 11 | Q28: =SUM(O28:P28) -> 0 | R28: 11 | V28: =SUM(T28:U28) -> 0 | W28: 11 | AA28: =SUM(Y28:Z28) -> 0 | AB28: 11 | AF28: =SUM(AD28:AE28) -> 0 | AG28: 11 | AK28: =SUM(AI28:AJ28) -> 0 | AL28: 11 | AP28: =SUM(AN28:AO28) -> 0 | AQ28: 11 | AU28: =SUM(AS28:AT28) -> 0 | AV28: 11 | AZ28: =SUM(AX28:AY28) -> 0 | BA28: 11 | BE28: =SUM(BC28:BD28) -> 0
H29: 12 | L29: =SUM(J29:K29) -> 0 | M29: 12 | Q29: =SUM(O29:P29) -> 0 | R29: 12 | V29: =SUM(T29:U29) -> 0 | W29: 12 | AA29: =SUM(Y29:Z29) -> 0 | AB29: 12 | AF29: =SUM(AD29:AE29) -> 0 | AG29: 12 | AK29: =SUM(AI29:AJ29) -> 0 | AL29: 12 | AP29: =SUM(AN29:AO29) -> 0 | AQ29: 12 | AU29: =SUM(AS29:AT29) -> 0 | AV29: 12 | AZ29: =SUM(AX29:AY29) -> 0 | BA29: 12 | BE29: =SUM(BC29:BD29) -> 0
... H73: 56 | L73: =SUM(J73:K73) -> 0 | M73: 56 | Q73: =SUM(O73:P73) -> 0 | R73: 56 | V73: =SUM(T73:U73) -> 0 | W73: 56 | AA73: =SUM(Y73:Z73) -> 0 | AB73: 56 | AF73: =SUM(AD73:AE73) -> 0 | AG73: 56 | AK73: =SUM(AI73:AJ73) -> 0 | AL73: 56 | AP73: =SUM(AN73:AO73) -> 0 | AQ73: 56 | AU73: =SUM(AS73:AT73) -> 0 | AV73: 56 | AZ73: =SUM(AX73:AY73) -> 0 | BA73: 56 | BE73: =SUM(BC73:BD73) -> 0

Sheet YAMAZUMI участка
H1: ='YAMAZUMI цеха'!H1 -> YAMAZUMI ""
H2: Количество операций: | M2: Расчётное количество операторов: | R2: Дата разработки: | V2: Разработал: | Z2: СТ расч: | AC2: =MAX(E5:E14)*1.1 -> 0 | AE2: расч. кол-во изделий
H3: =COUNTA(I18:I153,N18:N153,S18:S153,X18:X153,AC18:AC153) -> 0 | M3: =COUNTA(I18,N18,S18,X18,AC18) -> 0 | Z3: СТ: | AC3: =MAX(E5:E14) -> 0 | AE3: =25200/AC2 -> #DIV/0!
B4: Раб.места | C4: Польза | D4: Потери | E4: Общее | F4: ТТ
B5: Первое раб.место | C5: =J17 -> 0 | D5: =K17 -> 0 | E5: =L17 -> 0 | F5: =AC2 -> 0
B6: Второе раб.место | C6: =O17 -> 0 | D6: =P17 -> 0 | E6: =Q17 -> 0 | F6: =AC2 -> 0
B7: Третье раб.место | C7: =T17 -> 0 | D7: =U17 -> 0 | E7: =V17 -> 0 | F7: =AC2 -> 0
B8: Четвёртое раб.место | C8: =Y17 -> 0 | D8: =Z17 -> 0 | E8: =AA17 -> 0 | F8: =AC2 -> 0
B9: Пятое раб.место | C9: =AD17 -> 0 | D9: =AE17 -> 0 | E9: =AF17 -> 0 | F9: =AC2 -> 0
B10: Шестое раб.место | C10: =AI17 -> 0 | D10: =AJ17 -> 0 | E10: =AK17 -> 0 | F10: =AC2 -> 0
B11: Седьмое раб.место | C11: =AN17 -> 0 | D11: =AO17 -> 0 | E11: =AP17 -> 0 | F11: =AC2 -> 0
B12: Восьмое раб.место | C12: =AS17 -> 0 | D12: =AT17 -> 0 | E12: =AU17 -> 0 | F12: =AC2 -> 0
B13: Девятое раб.место | C13: =AX17 -> 0 | D13: =AY17 -> 0 | E13: =AZ17 -> 0 | F13: =AC2 -> 0
B14: Десятое раб.место | C14: =BC17 -> 0 | D14: =BD17 -> 0 | E14: =BE17 -> 0 | F14: =AC2 -> 0
H16: № | I16: Первое раб.место | J16: Польза | K16: Потери | L16: Общее | M16: № | N16: Второе раб.место | O16: Польза | P16: Потери | Q16: Общее | R16: № | S16: Третье раб.место | T16: Польза | U16: Потери | V16: Общее | W16: № | X16: Четвёртое раб.место | Y16: Польза | Z16: Потери | AA16: Общее | AB16: № | AC16: Пятое раб.место | AD16: Польза | AE16: Потери | AF16: Общее | AG16: № | AH16: Шестое раб.место | AI16: Польза | AJ16: Потери | AK16: Общее | AL16: № | AM16: Седьмое раб.место | AN16: Польза | AO16: Потери | AP16: Общее | AQ16: № | AR16: Восьмое раб.место | AS16: Польза | AT16: Потери | AU16: Общее | AV16: № | AW16: Девятое раб.место | AX16: Польза | AY16: Потери | AZ16: Общее | BA16: № | BB16: Десятое раб.место | BC16: Польза | BD16: Потери | BE16: Общее
I17: Суммарное время: | J17: =SUM(J18:J73) -> 0 | K17: =SUM(K18:K73) -> 0 | L17: =SUM(L18:L73) -> 0 | N17: Суммарное время: | O17: =SUM(O18:O73) -> 0 | P17: =SUM(P18:P73) -> 0 | Q17: =SUM(Q18:Q73) -> 0 | S17: Суммарное время: | T17: =SUM(T18:T73) -> 0 | U17: =SUM(U18:U73) -> 0 | V17: =SUM(V18:V73) -> 0 | X17: Суммарное время: | Y17: =SUM(Y18:Y73) -> 0 | Z17: =SUM(Z18:Z73) -> 0 | AA17: =SUM(AA18:AA73) -> 0 | AC17: Суммарное время: | AD17: =SUM(AD18:AD73) -> 0 | AE17: =SUM(AE18:AE73) -> 0 | AF17: =SUM(AF18:AF73) -> 0 | AH17: Суммарное время: | AI17: =SUM(AI18:AI73) -> 0 | AJ17: =SUM(AJ18:AJ73) -> 0 | AK17: =SUM(AK18:AK73) -> 0 | AM17: Суммарное время: | AN17: =SUM(AN18:AN73) -> 0 | AO17: =SUM(AO18:AO73) -> 0 | AP17: =SUM(AP18:AP73) -> 0 | AR17: Суммарное время: | AS17: =SUM(AS18:AS73) -> 0 | AT17: =SUM(AT18:AT73) -> 0 | AU17: =SUM(AU18:AU73) -> 0 | AW17: Суммарное время: | AX17: =SUM(AX18:AX73) -> 0 | AY17: =SUM(AY18:AY73) -> 0 | AZ17: =SUM(AZ18:AZ73) -> 0 | BB17: Суммарное время: | BC17: =SUM(BC18:BC73) -> 0 | BD17: =SUM(BD18:BD73) -> 0 | BE17: =SUM(BE18:BE73) -> 0
H18: 1 | L18: =SUM(J18:K18) -> 0 | M18: 1 | Q18: =SUM(O18:P18) -> 0 | R18: 1 | V18: =SUM(T18:U18) -> 0 | W18: 1 | AA18: =SUM(Y18:Z18) -> 0 | AB18: 1 | AF18: =SUM(AD18:AE18) -> 0 | AG18: 1 | AK18: =SUM(AI18:AJ18) -> 0 | AL18: 1 | AP18: =SUM(AN18:AO18) -> 0 | AQ18: 1 | AU18: =SUM(AS18:AT18) -> 0 | AV18: 1 | AZ18: =SUM(AX18:AY18) -> 0 | BA18: 1 | BE18: =SUM(BC18:BD18) -> 0
H19: 2 | L19: =SUM(J19:K19) -> 0 | M19: 2 | Q19: =SUM(O19:P19) -> 0 | R19: 2 | V19: =SUM(T19:U19) -> 0 | W19: 2 | AA19: =SUM(Y19:Z19) -> 0 | AB19: 2 | AF19: =SUM(AD19:AE19) -> 0 | AG19: 2 | AK19: =SUM(AI19:AJ19) -> 0 | AL19: 2 | AP19: =SUM(AN19:AO19) -> 0 | AQ19: 2 | AU19: =SUM(AS19:AT19) -> 0 | AV19: 2 | AZ19: =SUM(AX19:AY19) -> 0 | BA19: 2 | BE19: =SUM(BC19:BD19) -> 0
H20: 3 | L20: =SUM(J20:K20) -> 0 | M20: 3 | Q20: =SUM(O20:P20) -> 0 | R20: 3 | V20: =SUM(T20:U20) -> 0 | W20: 3 | AA20: =SUM(Y20:Z20) -> 0 | AB20: 3 | AF20: =SUM(AD20:AE20) -> 0 | AG20: 3 | AK20: =SUM(AI20:AJ20) -> 0 | AL20: 3 | AP20: =SUM(AN20:AO20) -> 0 | AQ20: 3 | AU20: =SUM(AS20:AT20) -> 0 | AV20: 3 | AZ20: =SUM(AX20:AY20) -> 0 | BA20: 3 | BE20: =SUM(BC20:BD20) -> 0
H21: 4 | L21: =SUM(J21:K21) -> 0 | M21: 4 | Q21: =SUM(O21:P21) -> 0 | R21: 4 | V21: =SUM(T21:U21) -> 0 | W21: 4 | AA21: =SUM(Y21:Z21) -> 0 | AB21: 4 | AF21: =SUM(AD21:AE21) -> 0 | AG21: 4 | AK21: =SUM(AI21:AJ21) -> 0 | AL21: 4 | AP21: =SUM(AN21:AO21) -> 0 | AQ21: 4 | AU21: =SUM(AS21:AT21) -> 0 | AV21: 4 | AZ21: =SUM(AX21:AY21) -> 0 | BA21: 4 | BE21: =SUM(BC21:BD21) -> 0
H22: 5 | L22: =SUM(J22:K22) -> 0 | M22: 5 | Q22: =SUM(O22:P22) -> 0 | R22: 5 | V22: =SUM(T22:U22) -> 0 | W22: 5 | AA22: =SUM(Y22:Z22) -> 0 | AB22: 5 | AF22: =SUM(AD22:AE22) -> 0 | AG22: 5 | AK22: =SUM(AI22:AJ22) -> 0 | AL22: 5 | AP22: =SUM(AN22:AO22) -> 0 | AQ22: 5 | AU22: =SUM(AS22:AT22) -> 0 | AV22: 5 | AZ22: =SUM(AX22:AY22) -> 0 | BA22: 5 | BE22: =SUM(BC22:BD22) -> 0
H23: 6 | L23: =SUM(J23:K23) -> 0 | M23: 6 | Q23: =SUM(O23:P23) -> 0 | R23: 6 | V23: =SUM(T23:U23) -> 0 | W23: 6 | AA23: =SUM(Y23:Z23) -> 0 | AB23: 6 | AF23: =SUM(AD23:AE23) -> 0 | AG23: 6 | AK23: =SUM(AI23:AJ23) -> 0 | AL23: 6 | AP23: =SUM(AN23:AO23) -> 0 | AQ23: 6 | AU23: =SUM(AS23:AT23) -> 0 | AV23: 6 | AZ23: =SUM(AX23:AY23) -> 0 | BA23: 6 | BE23: =SUM(BC23:BD23) -> 0
H24: 7 | L24: =SUM(J24:K24) -> 0 | M24: 7 | Q24: =SUM(O24:P24) -> 0 | R24: 7 | V24: =SUM(T24:U24) -> 0 | W24: 7 | AA24: =SUM(Y24:Z24) -> 0 | AB24: 7 | AF24: =SUM(AD24:AE24) -> 0 | AG24: 7 | AK24: =SUM(AI24:AJ24) -> 0 | AL24: 7 | AP24: =SUM(AN24:AO24) -> 0 | AQ24: 7 | AU24: =SUM(AS24:AT24) -> 0 | AV24: 7 | AZ24: =SUM(AX24:AY24) -> 0 | BA24: 7 | BE24: =SUM(BC24:BD24) -> 0
H25: 8 | L25: =SUM(J25:K25) -> 0 | M25: 8 | Q25: =SUM(O25:P25) -> 0 | R25: 8 | V25: =SUM(T25:U25) -> 0 | W25: 8 | AA25: =SUM(Y25:Z25) -> 0 | AB25: 8 | AF25: =SUM(AD25:AE25) -> 0 | AG25: 8 | AK25: =SUM(AI25:AJ25) -> 0 | AL25: 8 | AP25: =SUM(AN25:AO25) -> 0 | AQ25: 8 | AU25: =SUM(AS25:AT25) -> 0 | AV25: 8 | AZ25: =SUM(AX25:AY25) -> 0 | BA25: 8 | BE25: =SUM(BC25:BD25) -> 0
H26: 9 | L26: =SUM(J26:K26) -> 0 | M26: 9 | Q26: =SUM(O26:P26) -> 0 | R26: 9 | V26: =SUM(T26:U26) -> 0 | W26: 9 | AA26: =SUM(Y26:Z26) -> 0 | AB26: 9 | AF26: =SUM(AD26:AE26) -> 0 | AG26: 9 | AK26: =SUM(AI26:AJ26) -> 0 | AL26: 9 | AP26: =SUM(AN26:AO26) -> 0 | AQ26: 9 | AU26: =SUM(AS26:AT26) -> 0 | AV26: 9 | AZ26: =SUM(AX26:AY26) -> 0 | BA26: 9 | BE26: =SUM(BC26:BD26) -> 0
H27: 10 | L27: =SUM(J27:K27) -> 0 | M27: 10 | Q27: =SUM(O27:P27) -> 0 | R27: 10 | V27: =SUM(T27:U27) -> 0 | W27: 10 | AA27: =SUM(Y27:Z27) -> 0 | AB27: 10 | AF27: =SUM(AD27:AE27) -> 0 | AG27: 10 | AK27: =SUM(AI27:AJ27) -> 0 | AL27: 10 | AP27: =SUM(AN27:AO27) -> 0 | AQ27: 10 | AU27: =SUM(AS27:AT27) -> 0 | AV27: 10 | AZ27: =SUM(AX27:AY27) -> 0 | BA27: 10 | BE27: =SUM(BC27:BD27) -> 0
H28: 11 | L28: =SUM(J28:K28) -> 0 | M28: 11 | Q28: =SUM(O28:P28) -> 0 | R28: 11 | V28: =SUM(T28:U28) -> 0 | W28: 11 | AA28: =SUM(Y28:Z28) -> 0 | AB28: 11 | AF28: =SUM(AD28:AE28) -> 0 | AG28: 11 | AK28: =SUM(AI28:AJ28) -> 0 | AL28: 11 | AP28: =SUM(AN28:AO28) -> 0 | AQ28: 11 | AU28: =SUM(AS28:AT28) -> 0 | AV28: 11 | AZ28: =SUM(AX28:AY28) -> 0 | BA28: 11 | BE28: =SUM(BC28:BD28) -> 0
H29: 12 | L29: =SUM(J29:K29) -> 0 | M29: 12 | Q29: =SUM(O29:P29) -> 0 | R29: 12 | V29: =SUM(T29:U29) -> 0 | W29: 12 | AA29: =SUM(Y29:Z29) -> 0 | AB29: 12 | AF29: =SUM(AD29:AE29) -> 0 | AG29: 12 | AK29: =SUM(AI29:AJ29) -> 0 | AL29: 12 | AP29: =SUM(AN29:AO29) -> 0 | AQ29: 12 | AU29: =SUM(AS29:AT29) -> 0 | AV29: 12 | AZ29: =SUM(AX29:AY29) -> 0 | BA29: 12 | BE29: =SUM(BC29:BD29) -> 0
... H73: 56 | L73: =SUM(J73:K73) -> 0 | M73: 56 | Q73: =SUM(O73:P73) -> 0 | R73: 56 | V73: =SUM(T73:U73) -> 0 | W73: 56 | AA73: =SUM(Y73:Z73) -> 0 | AB73: 56 | AF73: =SUM(AD73:AE73) -> 0 | AG73: 56 | AK73: =SUM(AI73:AJ73) -> 0 | AL73: 56 | AP73: =SUM(AN73:AO73) -> 0 | AQ73: 56 | AU73: =SUM(AS73:AT73) -> 0 | AV73: 56 | AZ73: =SUM(AX73:AY73) -> 0 | BA73: 56 | BE73: =SUM(BC73:BD73) -> 0

Sheet ПРСБ 3
H1: ='YAMAZUMI цеха'!H1 -> YAMAZUMI ""
H2: Количество операций: | M2: Расчётное количество операторов: | R2: Дата разработки: | V2: Разработал: | Z2: СТ расч: | AC2: =MAX(E5:E14)*1.1 -> 0 | AE2: расч. кол-во изделий
H3: =COUNTA(I18:I153,N18:N153,S18:S153,X18:X153,AC18:AC153) -> 0 | M3: =COUNTA(I18,N18,S18,X18,AC18) -> 0 | R3: ='YAMAZUMI цеха'!R3 -> 0 | Z3: СТ: | AC3: =MAX(E5:E14) -> 0 | AE3: =26700/AC2 -> #DIV/0!
B4: Раб.места | C4: Польза | D4: Потери | E4: Общее | F4: ТТ
B5: Первое раб.место | C5: =J17 -> 0 | D5: =K17 -> 0 | E5: =L17 -> 0 | F5: =AC2 -> 0
B6: Второе раб.место | C6: =O17 -> 0 | D6: =P17 -> 0 | E6: =Q17 -> 0 | F6: =AC2 -> 0
B7: Третье раб.место | C7: =T17 -> 0 | D7: =U17 -> 0 | E7: =V17 -> 0 | F7: =AC2 -> 0
B8: Четвёртое раб.место | C8: =Y17 -> 0 | D8: =Z17 -> 0 | E8: =AA17 -> 0 | F8: =AC2 -> 0
B9: Пятое раб.место | C9: =AD17 -> 0 | D9: =AE17 -> 0 | E9: =AF17 -> 0 | F9: =AC2 -> 0
B10: Шестое раб.место | C10: =AI17 -> 0 | D10: =AJ17 -> 0 | E10: =AK17 -> 0 | F10: =AC2 -> 0
B11: Седьмое раб.место | C11: =AN17 -> 0 | D11: =AO17 -> 0 | E11: =AP17 -> 0 | F11: =AC2 -> 0
B12: Восьмое раб.место | C12: =AS17 -> 0 | D12: =AT17 -> 0 | E12: =AU17 -> 0 | F12: =AC2 -> 0
B13: Девятое раб.место | C13: =AX17 -> 0 | D13: =AY17 -> 0 | E13: =AZ17 -> 0 | F13: =AC2 -> 0
B14: Десятое раб.место | C14: =BC17 -> 0 | D14: =BD17 -> 0 | E14: =BE17 -> 0 | F14: =AC2 -> 0
H16: № | I16: Первое раб.место | J16: Польза | K16: Потери | L16: Общее | M16: № | N16: Второе раб.место | O16: Польза | P16: Потери | Q16: Общее | R16: № | S16: Третье раб.место | T16: Польза | U16: Потери | V16: Общее | W16: № | X16: Четвёртое раб.место | Y16: Польза | Z16: Потери | AA16: Общее | AB16: № | AC16: Пятое раб.место | AD16: Польза | AE16: Потери | AF16: Общее | AG16: № | AH16: Шестое раб.место | AI16: Польза | AJ16: Потери | AK16: Общее | AL16: № | AM16: Седьмое раб.место | AN16: Польза | AO16: Потери | AP16: Общее | AQ16: № | AR16: Восьмое раб.место | AS16: Польза | AT16: Потери | AU16: Общее | AV16: № | AW16: Девятое раб.место | AX16: Польза | AY16: Потери | AZ16: Общее | BA16: № | BB16: Десятое раб.место | BC16: Польза | BD16: Потери | BE16: Общее
I17: Суммарное время: | J17: =SUM(J18:J73) -> 0 | K17: =SUM(K18:K73) -> 0 | L17: =SUM(L18:L73) -> 0 | N17: Суммарное время: | O17: =SUM(O18:O73) -> 0 | P17: =SUM(P18:P73) -> 0 | Q17: =SUM(Q18:Q73) -> 0 | S17: Суммарное время: | T17: =SUM(T18:T73) -> 0 | U17: =SUM(U18:U73) -> 0 | V17: =SUM(V18:V73) -> 0 | X17: Суммарное время: | Y17: =SUM(Y18:Y73) -> 0 | Z17: =SUM(Z18:Z73) -> 0 | AA17: =SUM(AA18:AA73) -> 0 | AC17: Суммарное время: | AD17: =SUM(AD18:AD73) -> 0 | AE17: =SUM(AE18:AE73) -> 0 | AF17: =SUM(AF18:AF73) -> 0 | AH17: Суммарное время: | AI17: =SUM(AI18:AI73) -> 0 | AJ17: =SUM(AJ18:AJ73) -> 0 | AK17: =SUM(AK18:AK73) -> 0 | AM17: Суммарное время: | AN17: =SUM(AN18:AN73) -> 0 | AO17: =SUM(AO18:AO73) -> 0 | AP17: =SUM(AP18:AP73) -> 0 | AR17: Суммарное время: | AS17: =SUM(AS18:AS73) -> 0 | AT17: =SUM(AT18:AT73) -> 0 | AU17: =SUM(AU18:AU73) -> 0 | AW17: Суммарное время: | AX17: =SUM(AX18:AX73) -> 0 | AY17: =SUM(AY18:AY73) -> 0 | AZ17: =SUM(AZ18:AZ73) -> 0 | BB17: Суммарное время: | BC17: =SUM(BC18:BC73) -> 0 | BD17: =SUM(BD18:BD73) -> 0 | BE17: =SUM(BE18:BE73) -> 0
H18: 1 | L18: =SUM(J18:K18) -> 0 | M18: 1 | Q18: =SUM(O18:P18) -> 0 | R18: 1 | V18: =SUM(T18:U18) -> 0 | W18: 1 | AA18: =SUM(Y18:Z18) -> 0 | AB18: 1 | AF18: =SUM(AD18:AE18) -> 0 | AG18: 1 | AK18: =SUM(AI18:AJ18) -> 0 | AL18: 1 | AP18: =SUM(AN18:AO18) -> 0 | AQ18: 1 | AU18: =SUM(AS18:AT18) -> 0 | AV18: 1 | AZ18: =SUM(AX18:AY18) -> 0 | BA18: 1 | BE18: =SUM(BC18:BD18) -> 0
H19: 2 | L19: =SUM(J19:K19) -> 0 | M19: 2 | Q19: =SUM(O19:P19) -> 0 | R19: 2 | V19: =SUM(T19:U19) -> 0 | W19: 2 | AA19: =SUM(Y19:Z19) -> 0 | AB19: 2 | AF19: =SUM(AD19:AE19) -> 0 | AG19: 2 | AK19: =SUM(AI19:AJ19) -> 0 | AL19: 2 | AP19: =SUM(AN19:AO19) -> 0 | AQ19: 2 | AU19: =SUM(AS19:AT19) -> 0 | AV19: 2 | AZ19: =SUM(AX19:AY19) -> 0 | BA19: 2 | BE19: =SUM(BC19:BD19) -> 0
H20: 3 | L20: =SUM(J20:K20) -> 0 | M20: 3 | Q20: =SUM(O20:P20) -> 0 | R20: 3 | V20: =SUM(T20:U20) -> 0 | W20: 3 | AA20: =SUM(Y20:Z20) -> 0 | AB20: 3 | AF20: =SUM(AD20:AE20) -> 0 | AG20: 3 | AK20: =SUM(AI20:AJ20) -> 0 | AL20: 3 | AP20: =SUM(AN20:AO20) -> 0 | AQ20: 3 | AU20: =SUM(AS20:AT20) -> 0 | AV20: 3 | AZ20: =SUM(AX20:AY20) -> 0 | BA20: 3 | BE20: =SUM(BC20:BD20) -> 0
H21: 4 | L21: =SUM(J21:K21) -> 0 | M21: 4 | Q21: =SUM(O21:P21) -> 0 | R21: 4 | V21: =SUM(T21:U21) -> 0 | W21: 4 | AA21: =SUM(Y21:Z21) -> 0 | AB21: 4 | AF21: =SUM(AD21:AE21) -> 0 | AG21: 4 | AK21: =SUM(AI21:AJ21) -> 0 | AL21: 4 | AP21: =SUM(AN21:AO21) -> 0 | AQ21: 4 | AU21: =SUM(AS21:AT21) -> 0 | AV21: 4 | AZ21: =SUM(AX21:AY21) -> 0 | BA21: 4 | BE21: =SUM(BC21:BD21) -> 0
H22: 5 | L22: =SUM(J22:K22) -> 0 | M22: 5 | Q22: =SUM(O22:P22) -> 0 | R22: 5 | V22: =SUM(T22:U22) -> 0 | W22: 5 | AA22: =SUM(Y22:Z22) -> 0 | AB22: 5 | AF22: =SUM(AD22:AE22) -> 0 | AG22: 5 | AK22: =SUM(AI22:AJ22) -> 0 | AL22: 5 | AP22: =SUM(AN22:AO22) -> 0 | AQ22: 5 | AU22: =SUM(AS22:AT22) -> 0 | AV22: 5 | AZ22: =SUM(AX22:AY22) -> 0 | BA22: 5 | BE22: =SUM(BC22:BD22) -> 0
H23: 6 | L23: =SUM(J23:K23) -> 0 | M23: 6 | Q23: =SUM(O23:P23) -> 0 | R23: 6 | V23: =SUM(T23:U23) -> 0 | W23: 6 | AA23: =SUM(Y23:Z23) -> 0 | AB23: 6 | AF23: =SUM(AD23:AE23) -> 0 | AG23: 6 | AK23: =SUM(AI23:AJ23) -> 0 | AL23: 6 | AP23: =SUM(AN23:AO23) -> 0 | AQ23: 6 | AU23: =SUM(AS23:AT23) -> 0 | AV23: 6 | AZ23: =SUM(AX23:AY23) -> 0 | BA23: 6 | BE23: =SUM(BC23:BD23) -> 0
H24: 7 | L24: =SUM(J24:K24) -> 0 | M24: 7 | Q24: =SUM(O24:P24) -> 0 | R24: 7 | V24: =SUM(T24:U24) -> 0 | W24: 7 | AA24: =SUM(Y24:Z24) -> 0 | AB24: 7 | AF24: =SUM(AD24:AE24) -> 0 | AG24: 7 | AK24: =SUM(AI24:AJ24) -> 0 | AL24: 7 | AP24: =SUM(AN24:AO24) -> 0 | AQ24: 7 | AU24: =SUM(AS24:AT24) -> 0 | AV24: 7 | AZ24: =SUM(AX24:AY24) -> 0 | BA24: 7 | BE24: =SUM(BC24:BD24) -> 0
H25: 8 | L25: =SUM(J25:K25) -> 0 | M25: 8 | Q25: =SUM(O25:P25) -> 0 | R25: 8 | V25: =SUM(T25:U25) -> 0 | W25: 8 | AA25: =SUM(Y25:Z25) -> 0 | AB25: 8 | AF25: =SUM(AD25:AE25) -> 0 | AG25: 8 | AK25: =SUM(AI25:AJ25) -> 0 | AL25: 8 | AP25: =SUM(AN25:AO25) -> 0 | AQ25: 8 | AU25: =SUM(AS25:AT25) -> 0 | AV25: 8 | AZ25: =SUM(AX25:AY25) -> 0 | BA25: 8 | BE25: =SUM(BC25:BD25) -> 0
H26: 9 | L26: =SUM(J26:K26) -> 0 | M26: 9 | Q26: =SUM(O26:P26) -> 0 | R26: 9 | V26: =SUM(T26:U26) -> 0 | W26: 9 | AA26: =SUM(Y26:Z26) -> 0 | AB26: 9 | AF26: =SUM(AD26:AE26) -> 0 | AG26: 9 | AK26: =SUM(AI26:AJ26) -> 0 | AL26: 9 | AP26: =SUM(AN26:AO26) -> 0 | AQ26: 9 | AU26: =SUM(AS26:AT26) -> 0 | AV26: 9 | AZ26: =SUM(AX26:AY26) -> 0 | BA26: 9 | BE26: =SUM(BC26:BD26) -> 0
H27: 10 | L27: =SUM(J27:K27) -> 0 | M27: 10 | Q27: =SUM(O27:P27) -> 0 | R27: 10 | V27: =SUM(T27:U27) -> 0 | W27: 10 | AA27: =SUM(Y27:Z27) -> 0 | AB27: 10 | AF27: =SUM(AD27:AE27) -> 0 | AG27: 10 | AK27: =SUM(AI27:AJ27) -> 0 | AL27: 10 | AP27: =SUM(AN27:AO27) -> 0 | AQ27: 10 | AU27: =SUM(AS27:AT27) -> 0 | AV27: 10 | AZ27: =SUM(AX27:AY27) -> 0 | BA27: 10 | BE27: =SUM(BC27:BD27) -> 0
H28: 11 | L28: =SUM(J28:K28) -> 0 | M28: 11 | Q28: =SUM(O28:P28) -> 0 | R28: 11 | V28: =SUM(T28:U28) -> 0 | W28: 11 | AA28: =SUM(Y28:Z28) -> 0 | AB28: 11 | AF28: =SUM(AD28:AE28) -> 0 | AG28: 11 | AK28: =SUM(AI28:AJ28) -> 0 | AL28: 11 | AP28: =SUM(AN28:AO28) -> 0 | AQ28: 11 | AU28: =SUM(AS28:AT28) -> 0 | AV28: 11 | AZ28: =SUM(AX28:AY28) -> 0 | BA28: 11 | BE28: =SUM(BC28:BD28) -> 0
H29: 12 | L29: =SUM(J29:K29) -> 0 | M29: 12 | Q29: =SUM(O29:P29) -> 0 | R29: 12 | V29: =SUM(T29:U29) -> 0 | W29: 12 | AA29: =SUM(Y29:Z29) -> 0 | AB29: 12 | AF29: =SUM(AD29:AE29) -> 0 | AG29: 12 | AK29: =SUM(AI29:AJ29) -> 0 | AL29: 12 | AP29: =SUM(AN29:AO29) -> 0 | AQ29: 12 | AU29: =SUM(AS29:AT29) -> 0 | AV29: 12 | AZ29: =SUM(AX29:AY29) -> 0 | BA29: 12 | BE29: =SUM(BC29:BD29) -> 0
... H73: 56 | L73: =SUM(J73:K73) -> 0 | M73: 56 | Q73: =SUM(O73:P73) -> 0 | R73: 56 | V73: =SUM(T73:U73) -> 0 | W73: 56 | AA73: =SUM(Y73:Z73) -> 0 | AB73: 56 | AF73: =SUM(AD73:AE73) -> 0 | AG73: 56 | AK73: =SUM(AI73:AJ73) -> 0 | AL73: 56 | AP73: =SUM(AN73:AO73) -> 0 | AQ73: 56 | AU73: =SUM(AS73:AT73) -> 0 | AV73: 56 | AZ73: =SUM(AX73:AY73) -> 0 | BA73: 56 | BE73: =SUM(BC73:BD73) -> 0

Sheet ПРСБ 4
H1: ='YAMAZUMI цеха'!H1 -> YAMAZUMI ""
H2: Количество операций: | M2: Расчётное количество операторов: | R2: Дата разработки: | V2: Разработал: | Z2: СТ расч: | AC2: =MAX(E5:E14)*1.1 -> 0 | AE2: расч. кол-во изделий
H3: =COUNTA(I18:I153,N18:N153,S18:S153,X18:X153,AC18:AC153) -> 0 | M3: =COUNTA(I18,N18,S18,X18,AC18) -> 0 | R3: ='YAMAZUMI цеха'!R3 -> 0 | Z3: СТ: | AC3: =MAX(E5:E14) -> 0 | AE3: =26700/AC2 -> #DIV/0!
B4: Раб.места | C4: Польза | D4: Потери | E4: Общее | F4: ТТ
B5: Первое раб.место | C5: =J17 -> 0 | D5: =K17 -> 0 | E5: =L17 -> 0 | F5: =AC2 -> 0
B6: Второе раб.место | C6: =O17 -> 0 | D6: =P17 -> 0 | E6: =Q17 -> 0 | F6: =AC2 -> 0
B7: Третье раб.место | C7: =T17 -> 0 | D7: =U17 -> 0 | E7: =V17 -> 0 | F7: =AC2 -> 0
B8: Четвёртое раб.место | C8: =Y17 -> 0 | D8: =Z17 -> 0 | E8: =AA17 -> 0 | F8: =AC2 -> 0
B9: Пятое раб.место | C9: =AD17 -> 0 | D9: =AE17 -> 0 | E9: =AF17 -> 0 | F9: =AC2 -> 0
B10: Шестое раб.место | C10: =AI17 -> 0 | D10: =AJ17 -> 0 | E10: =AK17 -> 0 | F10: =AC2 -> 0
B11: Седьмое раб.место | C11: =AN17 -> 0 | D11: =AO17 -> 0 | E11: =AP17 -> 0 | F11: =AC2 -> 0
B12: Восьмое раб.место | C12: =AS17 -> 0 | D12: =AT17 -> 0 | E12: =AU17 -> 0 | F12: =AC2 -> 0
B13: Девятое раб.место | C13: =AX17 -> 0 | D13: =AY17 -> 0 | E13: =AZ17 -> 0 | F13: =AC2 -> 0
B14: Десятое раб.место | C14: =BC17 -> 0 | D14: =BD17 -> 0 | E14: =BE17 -> 0 | F14: =AC2 -> 0
H16: № | I16: Первое раб.место | J16: Польза | K16: Потери | L16: Общее | M16: № | N16: Второе раб.место | O16: Польза | P16: Потери | Q16: Общее | R16: № | S16: Третье раб.место | T16: Польза | U16: Потери | V16: Общее | W16: № | X16: Четвёртое раб.место | Y16: Польза | Z16: Потери | AA16: Общее | AB16: № | AC16: Пятое раб.место | AD16: Польза | AE16: Потери | AF16: Общее | AG16: № | AH16: Шестое раб.место | AI16: Польза | AJ16: Потери | AK16: Общее | AL16: № | AM16: Седьмое раб.место | AN16: Польза | AO16: Потери | AP16: Общее | AQ16: № | AR16: Восьмое раб.место | AS16: Польза | AT16: Потери | AU16: Общее | AV16: № | AW16: Девятое раб.место | AX16: Польза | AY16: Потери | AZ16: Общее | BA16: № | BB16: Десятое раб.место | BC16: Польза | BD16: Потери | BE16: Общее
I17: Суммарное время: | J17: =SUM(J18:J73) -> 0 | K17: =SUM(K18:K73) -> 0 | L17: =SUM(L18:L73) -> 0 | N17: Суммарное время: | O17: =SUM(O18:O73) -> 0 | P17: =SUM(P18:P73) -> 0 | Q17: =SUM(Q18:Q73) -> 0 | S17: Суммарное время: | T17: =SUM(T18:T73) -> 0 | U17: =SUM(U18:U73) -> 0 | V17: =SUM(V18:V73) -> 0 | X17: Суммарное время: | Y17: =SUM(Y18:Y73) -> 0 | Z17: =SUM(Z18:Z73) -> 0 | AA17: =SUM(AA18:AA73) -> 0 | AC17: Суммарное время: | AD17: =SUM(AD18:AD73) -> 0 | AE17: =SUM(AE18:AE73) -> 0 | AF17: =SUM(AF18:AF73) -> 0 | AH17: Суммарное время: | AI17: =SUM(AI18:AI73) -> 0 | AJ17: =SUM(AJ18:AJ73) -> 0 | AK17: =SUM(AK18:AK73) -> 0 | AM17: Суммарное время: | AN17: =SUM(AN18:AN73) -> 0 | AO17: =SUM(AO18:AO73) -> 0 | AP17: =SUM(AP18:AP73) -> 0 | AR17: Суммарное время: | AS17: =SUM(AS18:AS73) -> 0 | AT17: =SUM(AT18:AT73) -> 0 | AU17: =SUM(AU18:AU73) -> 0 | AW17: Суммарное время: | AX17: =SUM(AX18:AX73) -> 0 | AY17: =SUM(AY18:AY73) -> 0 | AZ17: =SUM(AZ18:AZ73) -> 0 | BB17: Суммарное время: | BC17: =SUM(BC18:BC73) -> 0 | BD17: =SUM(BD18:BD73) -> 0 | BE17: =SUM(BE18:BE73) -> 0
H18: 1 | L18: =SUM(J18:K18) -> 0 | M18: 1 | Q18: =SUM(O18:P18) -> 0 | R18: 1 | V18: =SUM(T18:U18) -> 0 | W18: 1 | AA18: =SUM(Y18:Z18) -> 0 | AB18: 1 | AF18: =SUM(AD18:AE18) -> 0 | AG18: 1 | AK18: =SUM(AI18:AJ18) -> 0 | AL18: 1 | AP18: =SUM(AN18:AO18) -> 0 | AQ18: 1 | AU18: =SUM(AS18:AT18) -> 0 | AV18: 1 | AZ18: =SUM(AX18:AY18) -> 0 | BA18: 1 | BE18: =SUM(BC18:BD18) -> 0
H19: 2 | L19: =SUM(J19:K19) -> 0 | M19: 2 | Q19: =SUM(O19:P19) -> 0 | R19: 2 | V19: =SUM(T19:U19) -> 0 | W19: 2 | AA19: =SUM(Y19:Z19) -> 0 | AB19: 2 | AF19: =SUM(AD19:AE19) -> 0 | AG19: 2 | AK19: =SUM(AI19:AJ19) -> 0 | AL19: 2 | AP19: =SUM(AN19:AO19) -> 0 | AQ19: 2 | AU19: =SUM(AS19:AT19) -> 0 | AV19: 2 | AZ19: =SUM(AX19:AY19) -> 0 | BA19: 2 | BE19: =SUM(BC19:BD19) -> 0
H20: 3 | L20: =SUM(J20:K20) -> 0 | M20: 3 | Q20: =SUM(O20:P20) -> 0 | R20: 3 | V20: =SUM(T20:U20) -> 0 | W20: 3 | AA20: =SUM(Y20:Z20) -> 0 | AB20: 3 | AF20: =SUM(AD20:AE20) -> 0 | AG20: 3 | AK20: =SUM(AI20:AJ20) -> 0 | AL20: 3 | AP20: =SUM(AN20:AO20) -> 0 | AQ20: 3 | AU20: =SUM(AS20:AT20) -> 0 | AV20: 3 | AZ20: =SUM(AX20:AY20) -> 0 | BA20: 3 | BE20: =SUM(BC20:BD20) -> 0
H21: 4 | L21: =SUM(J21:K21) -> 0 | M21: 4 | Q21: =SUM(O21:P21) -> 0 | R21: 4 | V21: =SUM(T21:U21) -> 0 | W21: 4 | AA21: =SUM(Y21:Z21) -> 0 | AB21: 4 | AF21: =SUM(AD21:AE21) -> 0 | AG21: 4 | AK21: =SUM(AI21:AJ21) -> 0 | AL21: 4 | AP21: =SUM(AN21:AO21) -> 0 | AQ21: 4 | AU21: =SUM(AS21:AT21) -> 0 | AV21: 4 | AZ21: =SUM(AX21:AY21) -> 0 | BA21: 4 | BE21: =SUM(BC21:BD21) -> 0
H22: 5 | L22: =SUM(J22:K22) -> 0 | M22: 5 | Q22: =SUM(O22:P22) -> 0 | R22: 5 | V22: =SUM(T22:U22) -> 0 | W22: 5 | AA22: =SUM(Y22:Z22) -> 0 | AB22: 5 | AF22: =SUM(AD22:AE22) -> 0 | AG22: 5 | AK22: =SUM(AI22:AJ22) -> 0 | AL22: 5 | AP22: =SUM(AN22:AO22) -> 0 | AQ22: 5 | AU22: =SUM(AS22:AT22) -> 0 | AV22: 5 | AZ22: =SUM(AX22:AY22) -> 0 | BA22: 5 | BE22: =SUM(BC22:BD22) -> 0
H23: 6 | L23: =SUM(J23:K23) -> 0 | M23: 6 | Q23: =SUM(O23:P23) -> 0 | R23: 6 | V23: =SUM(T23:U23) -> 0 | W23: 6 | AA23: =SUM(Y23:Z23) -> 0 | AB23: 6 | AF23: =SUM(AD23:AE23) -> 0 | AG23: 6 | AK23: =SUM(AI23:AJ23) -> 0 | AL23: 6 | AP23: =SUM(AN23:AO23) -> 0 | AQ23: 6 | AU23: =SUM(AS23:AT23) -> 0 | AV23: 6 | AZ23: =SUM(AX23:AY23) -> 0 | BA23: 6 | BE23: =SUM(BC23:BD23) -> 0
H24: 7 | L24: =SUM(J24:K24) -> 0 | M24: 7 | Q24: =SUM(O24:P24) -> 0 | R24: 7 | V24: =SUM(T24:U24) -> 0 | W24: 7 | AA24: =SUM(Y24:Z24) -> 0 | AB24: 7 | AF24: =SUM(AD24:AE24) -> 0 | AG24: 7 | AK24: =SUM(AI24:AJ24) -> 0 | AL24: 7 | AP24: =SUM(AN24:AO24) -> 0 | AQ24: 7 | AU24: =SUM(AS24:AT24) -> 0 | AV24: 7 | AZ24: =SUM(AX24:AY24) -> 0 | BA24: 7 | BE24: =SUM(BC24:BD24) -> 0
H25: 8 | L25: =SUM(J25:K25) -> 0 | M25: 8 | Q25: =SUM(O25:P25) -> 0 | R25: 8 | V25: =SUM(T25:U25) -> 0 | W25: 8 | AA25: =SUM(Y25:Z25) -> 0 | AB25: 8 | AF25: =SUM(AD25:AE25) -> 0 | AG25: 8 | AK25: =SUM(AI25:AJ25) -> 0 | AL25: 8 | AP25: =SUM(AN25:AO25) -> 0 | AQ25: 8 | AU25: =SUM(AS25:AT25) -> 0 | AV25: 8 | AZ25: =SUM(AX25:AY25) -> 0 | BA25: 8 | BE25: =SUM(BC25:BD25) -> 0
H26: 9 | L26: =SUM(J26:K26) -> 0 | M26: 9 | Q26: =SUM(O26:P26) -> 0 | R26: 9 | V26: =SUM(T26:U26) -> 0 | W26: 9 | AA26: =SUM(Y26:Z26) -> 0 | AB26: 9 | AF26: =SUM(AD26:AE26) -> 0 | AG26: 9 | AK26: =SUM(AI26:AJ26) -> 0 | AL26: 9 | AP26: =SUM(AN26:AO26) -> 0 | AQ26: 9 | AU26: =SUM(AS26:AT26) -> 0 | AV26: 9 | AZ26: =SUM(AX26:AY26) -> 0 | BA26: 9 | BE26: =SUM(BC26:BD26) -> 0
H27: 10 | L27: =SUM(J27:K27) -> 0 | M27: 10 | Q27: =SUM(O27:P27) -> 0 | R27: 10 | V27: =SUM(T27:U27) -> 0 | W27: 10 | AA27: =SUM(Y27:Z27) -> 0 | AB27: 10 | AF27: =SUM(AD27:AE27) -> 0 | AG27: 10 | AK27: =SUM(AI27:AJ27) -> 0 | AL27: 10 | AP27: =SUM(AN27:AO27) -> 0 | AQ27: 10 | AU27: =SUM(AS27:AT27) -> 0 | AV27: 10 | AZ27: =SUM(AX27:AY27) -> 0 | BA27: 10 | BE27: =SUM(BC27:BD27) -> 0
H28: 11 | L28: =SUM(J28:K28) -> 0 | M28: 11 | Q28: =SUM(O28:P28) -> 0 | R28: 11 | V28: =SUM(T28:U28) -> 0 | W28: 11 | AA28: =SUM(Y28:Z28) -> 0 | AB28: 11 | AF28: =SUM(AD28:AE28) -> 0 | AG28: 11 | AK28: =SUM(AI28:AJ28) -> 0 | AL28: 11 | AP28: =SUM(AN28:AO28) -> 0 | AQ28: 11 | AU28: =SUM(AS28:AT28) -> 0 | AV28: 11 | AZ28: =SUM(AX28:AY28) -> 0 | BA28: 11 | BE28: =SUM(BC28:BD28) -> 0
H29: 12 | L29: =SUM(J29:K29) -> 0 | M29: 12 | Q29: =SUM(O29:P29) -> 0 | R29: 12 | V29: =SUM(T29:U29) -> 0 | W29: 12 | AA29: =SUM(Y29:Z29) -> 0 | AB29: 12 | AF29: =SUM(AD29:AE29) -> 0 | AG29: 12 | AK29: =SUM(AI29:AJ29) -> 0 | AL29: 12 | AP29: =SUM(AN29:AO29) -> 0 | AQ29: 12 | AU29: =SUM(AS29:AT29) -> 0 | AV29: 12 | AZ29: =SUM(AX29:AY29) -> 0 | BA29: 12 | BE29: =SUM(BC29:BD29) -> 0
... H73: 56 | L73: =SUM(J73:K73) -> 0 | M73: 56 | Q73: =SUM(O73:P73) -> 0 | R73: 56 | V73: =SUM(T73:U73) -> 0 | W73: 56 | AA73: =SUM(Y73:Z73) -> 0 | AB73: 56 | AF73: =SUM(AD73:AE73) -> 0 | AG73: 56 | AK73: =SUM(AI73:AJ73) -> 0 | AL73: 56 | AP73: =SUM(AN73:AO73) -> 0 | AQ73: 56 | AU73: =SUM(AS73:AT73) -> 0 | AV73: 56 | AZ73: =SUM(AX73:AY73) -> 0 | BA73: 56 | BE73: =SUM(BC73:BD73) -> 0

Sheet СБ 3
H1: ='YAMAZUMI цеха'!H1 -> YAMAZUMI ""
H2: Количество операций: | M2: Расчётное количество операторов: | R2: Дата разработки: | V2: Разработал: | Z2: СТ расч: | AC2: =MAX(E5:E14)*1.1 -> 0 | AE2: расч. кол-во изделий
H3: =COUNTA(I18:I153,N18:N153,S18:S153,X18:X153,AC18:AC153) -> 0 | M3: =COUNTA(I18,N18,S18,X18,AC18) -> 0 | R3: ='YAMAZUMI цеха'!R3 -> 0 | Z3: СТ: | AC3: =MAX(E5:E14) -> 0 | AE3: =26700/AC2 -> #DIV/0!
B4: Раб.места | C4: Польза | D4: Потери | E4: Общее | F4: ТТ
B5: Первое раб.место | C5: =J17 -> 0 | D5: =K17 -> 0 | E5: =L17 -> 0 | F5: =AC2 -> 0
B6: Второе раб.место | C6: =O17 -> 0 | D6: =P17 -> 0 | E6: =Q17 -> 0 | F6: =AC2 -> 0
B7: Третье раб.место | C7: =T17 -> 0 | D7: =U17 -> 0 | E7: =V17 -> 0 | F7: =AC2 -> 0
B8: Четвёртое раб.место | C8: =Y17 -> 0 | D8: =Z17 -> 0 | E8: =AA17 -> 0 | F8: =AC2 -> 0
B9: Пятое раб.место | C9: =AD17 -> 0 | D9: =AE17 -> 0 | E9: =AF17 -> 0 | F9: =AC2 -> 0
B10: Шестое раб.место | C10: =AI17 -> 0 | D10: =AJ17 -> 0 | E10: =AK17 -> 0 | F10: =AC2 -> 0
B11: Седьмое раб.место | C11: =AN17 -> 0 | D11: =AO17 -> 0 | E11: =AP17 -> 0 | F11: =AC2 -> 0
B12: Восьмое раб.место | C12: =AS17 -> 0 | D12: =AT17 -> 0 | E12: =AU17 -> 0 | F12: =AC2 -> 0
B13: Девятое раб.место | C13: =AX17 -> 0 | D13: =AY17 -> 0 | E13: =AZ17 -> 0 | F13: =AC2 -> 0
B14: Десятое раб.место | C14: =BC17 -> 0 | D14: =BD17 -> 0 | E14: =BE17 -> 0 | F14: =AC2 -> 0
H16: № | I16: Первое раб.место | J16: Польза | K16: Потери | L16: Общее | M16: № | N16: Второе раб.место | O16: Польза | P16: Потери | Q16: Общее | R16: № | S16: Третье раб.место | T16: Польза | U16: Потери | V16: Общее | W16: № | X16: Четвёртое раб.место | Y16: Польза | Z16: Потери | AA16: Общее | AB16: № | AC16: Пятое раб.место | AD16: Польза | AE16: Потери | AF16: Общее | AG16: № | AH16: Шестое раб.место | AI16: Польза | AJ16: Потери | AK16: Общее | AL16: № | AM16: Седьмое раб.место | AN16: Польза | AO16: Потери | AP16: Общее | AQ16: № | AR16: Восьмое раб.место | AS16: Польза | AT16: Потери | AU16: Общее | AV16: № | AW16: Девятое раб.место | AX16: Польза | AY16: Потери | AZ16: Общее | BA16: № | BB16: Десятое раб.место | BC16: Польза | BD16: Потери | BE16: Общее
I17: Суммарное время: | J17: =SUM(J18:J73) -> 0 | K17: =SUM(K18:K73) -> 0 | L17: =SUM(L18:L73) -> 0 | N17: Суммарное время: | O17: =SUM(O18:O73) -> 0 | P17: =SUM(P18:P73) -> 0 | Q17: =SUM(Q18:Q73) -> 0 | S17: Суммарное время: | T17: =SUM(T18:T73) -> 0 | U17: =SUM(U18:U73) -> 0 | V17: =SUM(V18:V73) -> 0 | X17: Суммарное время: | Y17: =SUM(Y18:Y73) -> 0 | Z17: =SUM(Z18:Z73) -> 0 | AA17: =SUM(AA18:AA73) -> 0 | AC17: Суммарное время: | AD17: =SUM(AD18:AD73) -> 0 | AE17: =SUM(AE18:AE73) -> 0 | AF17: =SUM(AF18:AF73) -> 0 | AH17: Суммарное время: | AI17: =SUM(AI18:AI73) -> 0 | AJ17: =SUM(AJ18:AJ73) -> 0 | AK17: =SUM(AK18:AK73) -> 0 | AM17: Суммарное время: | AN17: =SUM(AN18:AN73) -> 0 | AO17: =SUM(AO18:AO73) -> 0 | AP17: =SUM(AP18:AP73) -> 0 | AR17: Суммарное время: | AS17: =SUM(AS18:AS73) -> 0 | AT17: =SUM(AT18:AT73) -> 0 | AU17: =SUM(AU18:AU73) -> 0 | AW17: Суммарное время: | AX17: =SUM(AX18:AX73) -> 0 | AY17: =SUM(AY18:AY73) -> 0 | AZ17: =SUM(AZ18:AZ73) -> 0 | BB17: Суммарное время: | BC17: =SUM(BC18:BC73) -> 0 | BD17: =SUM(BD18:BD73) -> 0 | BE17: =SUM(BE18:BE73) -> 0
H18: 1 | L18: =SUM(J18:K18) -> 0 | M18: 1 | Q18: =SUM(O18:P18) -> 0 | R18: 1 | V18: =SUM(T18:U18) -> 0 | W18: 1 | AA18: =SUM(Y18:Z18) -> 0 | AB18: 1 | AF18: =SUM(AD18:AE18) -> 0 | AG18: 1 | AK18: =SUM(AI18:AJ18) -> 0 | AL18: 1 | AP18: =SUM(AN18:AO18) -> 0 | AQ18: 1 | AU18: =SUM(AS18:AT18) -> 0 | AV18: 1 | AZ18: =SUM(AX18:AY18) -> 0 | BA18: 1 | BE18: =SUM(BC18:BD18) -> 0
H19: 2 | L19: =SUM(J19:K19) -> 0 | M19: 2 | Q19: =SUM(O19:P19) -> 0 | R19: 2 | V19: =SUM(T19:U19) -> 0 | W19: 2 | AA19: =SUM(Y19:Z19) -> 0 | AB19: 2 | AF19: =SUM(AD19:AE19) -> 0 | AG19: 2 | AK19: =SUM(AI19:AJ19) -> 0 | AL19: 2 | AP19: =SUM(AN19:AO19) -> 0 | AQ19: 2 | AU19: =SUM(AS19:AT19) -> 0 | AV19: 2 | AZ19: =SUM(AX19:AY19) -> 0 | BA19: 2 | BE19: =SUM(BC19:BD19) -> 0
H20: 3 | L20: =SUM(J20:K20) -> 0 | M20: 3 | Q20: =SUM(O20:P20) -> 0 | R20: 3 | V20: =SUM(T20:U20) -> 0 | W20: 3 | AA20: =SUM(Y20:Z20) -> 0 | AB20: 3 | AF20: =SUM(AD20:AE20) -> 0 | AG20: 3 | AK20: =SUM(AI20:AJ20) -> 0 | AL20: 3 | AP20: =SUM(AN20:AO20) -> 0 | AQ20: 3 | AU20: =SUM(AS20:AT20) -> 0 | AV20: 3 | AZ20: =SUM(AX20:AY20) -> 0 | BA20: 3 | BE20: =SUM(BC20:BD20) -> 0
H21: 4 | L21: =SUM(J21:K21) -> 0 | M21: 4 | Q21: =SUM(O21:P21) -> 0 | R21: 4 | V21: =SUM(T21:U21) -> 0 | W21: 4 | AA21: =SUM(Y21:Z21) -> 0 | AB21: 4 | AF21: =SUM(AD21:AE21) -> 0 | AG21: 4 | AK21: =SUM(AI21:AJ21) -> 0 | AL21: 4 | AP21: =SUM(AN21:AO21) -> 0 | AQ21: 4 | AU21: =SUM(AS21:AT21) -> 0 | AV21: 4 | AZ21: =SUM(AX21:AY21) -> 0 | BA21: 4 | BE21: =SUM(BC21:BD21) -> 0
